{
 "cells": [
  {
   "cell_type": "code",
   "execution_count": 9,
   "id": "411a5a64",
   "metadata": {},
   "outputs": [
    {
     "name": "stdout",
     "output_type": "stream",
     "text": [
      "Requirement already satisfied: jupyter in c:\\users\\work\\anaconda3\\lib\\site-packages (1.0.0)\n",
      "Requirement already satisfied: notebook in c:\\users\\work\\anaconda3\\lib\\site-packages (from jupyter) (6.4.12)\n",
      "Requirement already satisfied: qtconsole in c:\\users\\work\\anaconda3\\lib\\site-packages (from jupyter) (5.2.2)\n",
      "Requirement already satisfied: jupyter-console in c:\\users\\work\\anaconda3\\lib\\site-packages (from jupyter) (6.4.3)\n",
      "Requirement already satisfied: nbconvert in c:\\users\\work\\anaconda3\\lib\\site-packages (from jupyter) (6.4.4)\n",
      "Requirement already satisfied: ipykernel in c:\\users\\work\\anaconda3\\lib\\site-packages (from jupyter) (6.15.2)\n",
      "Requirement already satisfied: ipywidgets in c:\\users\\work\\anaconda3\\lib\\site-packages (from jupyter) (7.6.5)\n",
      "Requirement already satisfied: debugpy>=1.0 in c:\\users\\work\\anaconda3\\lib\\site-packages (from ipykernel->jupyter) (1.5.1)\n",
      "Requirement already satisfied: ipython>=7.23.1 in c:\\users\\work\\anaconda3\\lib\\site-packages (from ipykernel->jupyter) (7.31.1)\n",
      "Requirement already satisfied: jupyter-client>=6.1.12 in c:\\users\\work\\anaconda3\\lib\\site-packages (from ipykernel->jupyter) (7.3.4)\n",
      "Requirement already satisfied: matplotlib-inline>=0.1 in c:\\users\\work\\anaconda3\\lib\\site-packages (from ipykernel->jupyter) (0.1.6)\n",
      "Requirement already satisfied: nest-asyncio in c:\\users\\work\\anaconda3\\lib\\site-packages (from ipykernel->jupyter) (1.5.5)\n",
      "Requirement already satisfied: packaging in c:\\users\\work\\anaconda3\\lib\\site-packages (from ipykernel->jupyter) (21.3)\n",
      "Requirement already satisfied: psutil in c:\\users\\work\\anaconda3\\lib\\site-packages (from ipykernel->jupyter) (5.9.0)\n",
      "Requirement already satisfied: pyzmq>=17 in c:\\users\\work\\anaconda3\\lib\\site-packages (from ipykernel->jupyter) (23.2.0)\n",
      "Requirement already satisfied: tornado>=6.1 in c:\\users\\work\\anaconda3\\lib\\site-packages (from ipykernel->jupyter) (6.3.2)\n",
      "Requirement already satisfied: traitlets>=5.1.0 in c:\\users\\work\\anaconda3\\lib\\site-packages (from ipykernel->jupyter) (5.9.0)\n",
      "Requirement already satisfied: ipython-genutils~=0.2.0 in c:\\users\\work\\anaconda3\\lib\\site-packages (from ipywidgets->jupyter) (0.2.0)\n",
      "Requirement already satisfied: nbformat>=4.2.0 in c:\\users\\work\\anaconda3\\lib\\site-packages (from ipywidgets->jupyter) (5.5.0)\n",
      "Requirement already satisfied: widgetsnbextension~=3.5.0 in c:\\users\\work\\anaconda3\\lib\\site-packages (from ipywidgets->jupyter) (3.5.2)\n",
      "Requirement already satisfied: jupyterlab-widgets>=1.0.0 in c:\\users\\work\\anaconda3\\lib\\site-packages (from ipywidgets->jupyter) (1.0.0)\n",
      "Requirement already satisfied: prompt-toolkit!=3.0.0,!=3.0.1,<3.1.0,>=2.0.0 in c:\\users\\work\\anaconda3\\lib\\site-packages (from jupyter-console->jupyter) (3.0.20)\n",
      "Requirement already satisfied: pygments in c:\\users\\work\\anaconda3\\lib\\site-packages (from jupyter-console->jupyter) (2.15.1)\n",
      "Requirement already satisfied: mistune<2,>=0.8.1 in c:\\users\\work\\anaconda3\\lib\\site-packages (from nbconvert->jupyter) (0.8.4)\n",
      "Requirement already satisfied: jinja2>=2.4 in c:\\users\\work\\anaconda3\\lib\\site-packages (from nbconvert->jupyter) (2.11.3)\n",
      "Requirement already satisfied: jupyterlab-pygments in c:\\users\\work\\anaconda3\\lib\\site-packages (from nbconvert->jupyter) (0.1.2)\n",
      "Requirement already satisfied: jupyter-core in c:\\users\\work\\anaconda3\\lib\\site-packages (from nbconvert->jupyter) (4.11.1)\n",
      "Requirement already satisfied: entrypoints>=0.2.2 in c:\\users\\work\\anaconda3\\lib\\site-packages (from nbconvert->jupyter) (0.4)\n",
      "Requirement already satisfied: bleach in c:\\users\\work\\anaconda3\\lib\\site-packages (from nbconvert->jupyter) (4.1.0)\n",
      "Requirement already satisfied: pandocfilters>=1.4.1 in c:\\users\\work\\anaconda3\\lib\\site-packages (from nbconvert->jupyter) (1.5.0)\n",
      "Requirement already satisfied: testpath in c:\\users\\work\\anaconda3\\lib\\site-packages (from nbconvert->jupyter) (0.6.0)\n",
      "Requirement already satisfied: defusedxml in c:\\users\\work\\anaconda3\\lib\\site-packages (from nbconvert->jupyter) (0.7.1)\n",
      "Requirement already satisfied: beautifulsoup4 in c:\\users\\work\\anaconda3\\lib\\site-packages (from nbconvert->jupyter) (4.11.1)\n",
      "Requirement already satisfied: nbclient<0.6.0,>=0.5.0 in c:\\users\\work\\anaconda3\\lib\\site-packages (from nbconvert->jupyter) (0.5.13)\n",
      "Requirement already satisfied: argon2-cffi in c:\\users\\work\\anaconda3\\lib\\site-packages (from notebook->jupyter) (21.3.0)\n",
      "Requirement already satisfied: Send2Trash>=1.8.0 in c:\\users\\work\\anaconda3\\lib\\site-packages (from notebook->jupyter) (1.8.0)\n",
      "Requirement already satisfied: terminado>=0.8.3 in c:\\users\\work\\anaconda3\\lib\\site-packages (from notebook->jupyter) (0.13.1)\n",
      "Requirement already satisfied: prometheus-client in c:\\users\\work\\anaconda3\\lib\\site-packages (from notebook->jupyter) (0.14.1)\n",
      "Requirement already satisfied: qtpy in c:\\users\\work\\anaconda3\\lib\\site-packages (from qtconsole->jupyter) (2.2.0)\n",
      "Requirement already satisfied: setuptools>=18.5 in c:\\users\\work\\anaconda3\\lib\\site-packages (from ipython>=7.23.1->ipykernel->jupyter) (68.0.0)\n",
      "Requirement already satisfied: jedi>=0.16 in c:\\users\\work\\anaconda3\\lib\\site-packages (from ipython>=7.23.1->ipykernel->jupyter) (0.18.1)\n",
      "Requirement already satisfied: decorator in c:\\users\\work\\anaconda3\\lib\\site-packages (from ipython>=7.23.1->ipykernel->jupyter) (5.1.1)\n",
      "Requirement already satisfied: pickleshare in c:\\users\\work\\anaconda3\\lib\\site-packages (from ipython>=7.23.1->ipykernel->jupyter) (0.7.5)\n",
      "Requirement already satisfied: backcall in c:\\users\\work\\anaconda3\\lib\\site-packages (from ipython>=7.23.1->ipykernel->jupyter) (0.2.0)\n",
      "Requirement already satisfied: colorama in c:\\users\\work\\anaconda3\\lib\\site-packages (from ipython>=7.23.1->ipykernel->jupyter) (0.4.5)\n",
      "Requirement already satisfied: MarkupSafe>=0.23 in c:\\users\\work\\anaconda3\\lib\\site-packages (from jinja2>=2.4->nbconvert->jupyter) (2.0.1)\n",
      "Requirement already satisfied: python-dateutil>=2.8.2 in c:\\users\\work\\anaconda3\\lib\\site-packages (from jupyter-client>=6.1.12->ipykernel->jupyter) (2.8.2)\n",
      "Requirement already satisfied: pywin32>=1.0 in c:\\users\\work\\anaconda3\\lib\\site-packages (from jupyter-core->nbconvert->jupyter) (302)\n",
      "Requirement already satisfied: fastjsonschema in c:\\users\\work\\anaconda3\\lib\\site-packages (from nbformat>=4.2.0->ipywidgets->jupyter) (2.16.2)\n",
      "Requirement already satisfied: jsonschema>=2.6 in c:\\users\\work\\anaconda3\\lib\\site-packages (from nbformat>=4.2.0->ipywidgets->jupyter) (4.16.0)\n",
      "Requirement already satisfied: wcwidth in c:\\users\\work\\anaconda3\\lib\\site-packages (from prompt-toolkit!=3.0.0,!=3.0.1,<3.1.0,>=2.0.0->jupyter-console->jupyter) (0.2.5)\n",
      "Requirement already satisfied: pywinpty>=1.1.0 in c:\\users\\work\\anaconda3\\lib\\site-packages (from terminado>=0.8.3->notebook->jupyter) (2.0.2)\n",
      "Requirement already satisfied: argon2-cffi-bindings in c:\\users\\work\\anaconda3\\lib\\site-packages (from argon2-cffi->notebook->jupyter) (21.2.0)\n",
      "Requirement already satisfied: soupsieve>1.2 in c:\\users\\work\\anaconda3\\lib\\site-packages (from beautifulsoup4->nbconvert->jupyter) (2.3.1)\n",
      "Requirement already satisfied: six>=1.9.0 in c:\\users\\work\\anaconda3\\lib\\site-packages (from bleach->nbconvert->jupyter) (1.16.0)\n",
      "Requirement already satisfied: webencodings in c:\\users\\work\\anaconda3\\lib\\site-packages (from bleach->nbconvert->jupyter) (0.5.1)\n",
      "Requirement already satisfied: pyparsing!=3.0.5,>=2.0.2 in c:\\users\\work\\anaconda3\\lib\\site-packages (from packaging->ipykernel->jupyter) (3.0.9)\n",
      "Requirement already satisfied: parso<0.9.0,>=0.8.0 in c:\\users\\work\\anaconda3\\lib\\site-packages (from jedi>=0.16->ipython>=7.23.1->ipykernel->jupyter) (0.8.3)\n",
      "Requirement already satisfied: attrs>=17.4.0 in c:\\users\\work\\anaconda3\\lib\\site-packages (from jsonschema>=2.6->nbformat>=4.2.0->ipywidgets->jupyter) (21.4.0)\n",
      "Requirement already satisfied: pyrsistent!=0.17.0,!=0.17.1,!=0.17.2,>=0.14.0 in c:\\users\\work\\anaconda3\\lib\\site-packages (from jsonschema>=2.6->nbformat>=4.2.0->ipywidgets->jupyter) (0.18.0)\n",
      "Requirement already satisfied: cffi>=1.0.1 in c:\\users\\work\\anaconda3\\lib\\site-packages (from argon2-cffi-bindings->argon2-cffi->notebook->jupyter) (1.15.1)\n",
      "Requirement already satisfied: pycparser in c:\\users\\work\\anaconda3\\lib\\site-packages (from cffi>=1.0.1->argon2-cffi-bindings->argon2-cffi->notebook->jupyter) (2.21)\n"
     ]
    }
   ],
   "source": [
    "!pip install --upgrade jupyter"
   ]
  },
  {
   "cell_type": "code",
   "execution_count": 10,
   "id": "15cfb3bb",
   "metadata": {},
   "outputs": [
    {
     "name": "stderr",
     "output_type": "stream",
     "text": [
      "--- Logging error ---\n",
      "Traceback (most recent call last):\n",
      "  File \"C:\\Users\\Work\\anaconda3\\lib\\site-packages\\pip\\_internal\\utils\\logging.py\", line 177, in emit\n",
      "    self.console.print(renderable, overflow=\"ignore\", crop=False, style=style)\n",
      "  File \"C:\\Users\\Work\\anaconda3\\lib\\site-packages\\pip\\_vendor\\rich\\console.py\", line 1719, in print\n",
      "    self._buffer.extend(new_segments)\n",
      "  File \"C:\\Users\\Work\\anaconda3\\lib\\site-packages\\pip\\_vendor\\rich\\console.py\", line 864, in __exit__\n",
      "    self._exit_buffer()\n",
      "  File \"C:\\Users\\Work\\anaconda3\\lib\\site-packages\\pip\\_vendor\\rich\\console.py\", line 822, in _exit_buffer\n",
      "    self._check_buffer()\n",
      "  File \"C:\\Users\\Work\\anaconda3\\lib\\site-packages\\pip\\_vendor\\rich\\console.py\", line 2027, in _check_buffer\n",
      "    legacy_windows_render(buffer, LegacyWindowsTerm(self.file))\n",
      "  File \"C:\\Users\\Work\\anaconda3\\lib\\site-packages\\pip\\_vendor\\rich\\_windows_renderer.py\", line 19, in legacy_windows_render\n",
      "    term.write_text(text)\n",
      "  File \"C:\\Users\\Work\\anaconda3\\lib\\site-packages\\pip\\_vendor\\rich\\_win32_console.py\", line 403, in write_text\n",
      "    self.write(text)\n",
      "  File \"C:\\Users\\Work\\anaconda3\\lib\\encodings\\cp1251.py\", line 19, in encode\n",
      "    return codecs.charmap_encode(input,self.errors,encoding_table)[0]\n",
      "UnicodeEncodeError: 'charmap' codec can't encode character '\\xf6' in position 77: character maps to <undefined>\n",
      "Call stack:\n",
      "  File \"C:\\Users\\Work\\anaconda3\\lib\\runpy.py\", line 197, in _run_module_as_main\n",
      "    return _run_code(code, main_globals, None,\n",
      "  File \"C:\\Users\\Work\\anaconda3\\lib\\runpy.py\", line 87, in _run_code\n",
      "    exec(code, run_globals)\n",
      "  File \"C:\\Users\\Work\\anaconda3\\Scripts\\pip.exe\\__main__.py\", line 7, in <module>\n",
      "    sys.exit(main())\n",
      "  File \"C:\\Users\\Work\\anaconda3\\lib\\site-packages\\pip\\_internal\\cli\\main.py\", line 79, in main\n",
      "    return command.main(cmd_args)\n",
      "  File \"C:\\Users\\Work\\anaconda3\\lib\\site-packages\\pip\\_internal\\cli\\base_command.py\", line 101, in main\n",
      "    return self._main(args)\n",
      "  File \"C:\\Users\\Work\\anaconda3\\lib\\site-packages\\pip\\_internal\\cli\\base_command.py\", line 223, in _main\n",
      "    return run(options, args)\n",
      "  File \"C:\\Users\\Work\\anaconda3\\lib\\site-packages\\pip\\_internal\\cli\\base_command.py\", line 169, in exc_logging_wrapper\n",
      "    status = run_func(*args)\n",
      "  File \"C:\\Users\\Work\\anaconda3\\lib\\site-packages\\pip\\_internal\\cli\\req_command.py\", line 248, in wrapper\n",
      "    return func(self, options, args)\n",
      "  File \"C:\\Users\\Work\\anaconda3\\lib\\site-packages\\pip\\_internal\\commands\\install.py\", line 377, in run\n",
      "    requirement_set = resolver.resolve(\n",
      "  File \"C:\\Users\\Work\\anaconda3\\lib\\site-packages\\pip\\_internal\\resolution\\resolvelib\\resolver.py\", line 73, in resolve\n",
      "    collected = self.factory.collect_root_requirements(root_reqs)\n",
      "  File \"C:\\Users\\Work\\anaconda3\\lib\\site-packages\\pip\\_internal\\resolution\\resolvelib\\factory.py\", line 491, in collect_root_requirements\n",
      "    req = self._make_requirement_from_install_req(\n",
      "  File \"C:\\Users\\Work\\anaconda3\\lib\\site-packages\\pip\\_internal\\resolution\\resolvelib\\factory.py\", line 453, in _make_requirement_from_install_req\n",
      "    cand = self._make_candidate_from_link(\n",
      "  File \"C:\\Users\\Work\\anaconda3\\lib\\site-packages\\pip\\_internal\\resolution\\resolvelib\\factory.py\", line 206, in _make_candidate_from_link\n",
      "    self._link_candidate_cache[link] = LinkCandidate(\n",
      "  File \"C:\\Users\\Work\\anaconda3\\lib\\site-packages\\pip\\_internal\\resolution\\resolvelib\\candidates.py\", line 293, in __init__\n",
      "    super().__init__(\n",
      "  File \"C:\\Users\\Work\\anaconda3\\lib\\site-packages\\pip\\_internal\\resolution\\resolvelib\\candidates.py\", line 156, in __init__\n",
      "    self.dist = self._prepare()\n",
      "  File \"C:\\Users\\Work\\anaconda3\\lib\\site-packages\\pip\\_internal\\resolution\\resolvelib\\candidates.py\", line 225, in _prepare\n",
      "    dist = self._prepare_distribution()\n",
      "  File \"C:\\Users\\Work\\anaconda3\\lib\\site-packages\\pip\\_internal\\resolution\\resolvelib\\candidates.py\", line 304, in _prepare_distribution\n",
      "    return preparer.prepare_linked_requirement(self._ireq, parallel_builds=True)\n",
      "  File \"C:\\Users\\Work\\anaconda3\\lib\\site-packages\\pip\\_internal\\operations\\prepare.py\", line 485, in prepare_linked_requirement\n",
      "    self._log_preparing_link(req)\n",
      "  File \"C:\\Users\\Work\\anaconda3\\lib\\site-packages\\pip\\_internal\\operations\\prepare.py\", line 289, in _log_preparing_link\n",
      "    logger.info(message, information)\n",
      "  File \"C:\\Users\\Work\\anaconda3\\lib\\logging\\__init__.py\", line 1446, in info\n",
      "    self._log(INFO, msg, args, **kwargs)\n",
      "  File \"C:\\Users\\Work\\anaconda3\\lib\\logging\\__init__.py\", line 1589, in _log\n",
      "    self.handle(record)\n",
      "  File \"C:\\Users\\Work\\anaconda3\\lib\\logging\\__init__.py\", line 1599, in handle\n",
      "    self.callHandlers(record)\n",
      "  File \"C:\\Users\\Work\\anaconda3\\lib\\logging\\__init__.py\", line 1661, in callHandlers\n",
      "    hdlr.handle(record)\n",
      "  File \"C:\\Users\\Work\\anaconda3\\lib\\logging\\__init__.py\", line 952, in handle\n",
      "    self.emit(record)\n",
      "  File \"C:\\Users\\Work\\anaconda3\\lib\\site-packages\\pip\\_internal\\utils\\logging.py\", line 179, in emit\n",
      "    self.handleError(record)\n",
      "Message: 'Processing %s'\n",
      "Arguments: ('c:\\\\users\\\\work\\\\macromedia\\\\my_projekt_python_semester2\\\\05_github_ver\\xf6ffentlichung\\\\password_package',)\n",
      "--- Logging error ---\n",
      "Traceback (most recent call last):\n",
      "  File \"C:\\Users\\Work\\anaconda3\\lib\\site-packages\\pip\\_internal\\utils\\logging.py\", line 177, in emit\n",
      "    self.console.print(renderable, overflow=\"ignore\", crop=False, style=style)\n",
      "  File \"C:\\Users\\Work\\anaconda3\\lib\\site-packages\\pip\\_vendor\\rich\\console.py\", line 1719, in print\n",
      "    self._buffer.extend(new_segments)\n",
      "  File \"C:\\Users\\Work\\anaconda3\\lib\\site-packages\\pip\\_vendor\\rich\\console.py\", line 864, in __exit__\n",
      "    self._exit_buffer()\n",
      "  File \"C:\\Users\\Work\\anaconda3\\lib\\site-packages\\pip\\_vendor\\rich\\console.py\", line 822, in _exit_buffer\n",
      "    self._check_buffer()\n",
      "  File \"C:\\Users\\Work\\anaconda3\\lib\\site-packages\\pip\\_vendor\\rich\\console.py\", line 2027, in _check_buffer\n",
      "    legacy_windows_render(buffer, LegacyWindowsTerm(self.file))\n",
      "  File \"C:\\Users\\Work\\anaconda3\\lib\\site-packages\\pip\\_vendor\\rich\\_windows_renderer.py\", line 19, in legacy_windows_render\n",
      "    term.write_text(text)\n",
      "  File \"C:\\Users\\Work\\anaconda3\\lib\\site-packages\\pip\\_vendor\\rich\\_win32_console.py\", line 403, in write_text\n",
      "    self.write(text)\n",
      "  File \"C:\\Users\\Work\\anaconda3\\lib\\encodings\\cp1251.py\", line 19, in encode\n",
      "    return codecs.charmap_encode(input,self.errors,encoding_table)[0]\n",
      "UnicodeEncodeError: 'charmap' codec can't encode character '\\xf6' in position 77: character maps to <undefined>\n",
      "Call stack:\n",
      "  File \"C:\\Users\\Work\\anaconda3\\lib\\runpy.py\", line 197, in _run_module_as_main\n",
      "    return _run_code(code, main_globals, None,\n",
      "  File \"C:\\Users\\Work\\anaconda3\\lib\\runpy.py\", line 87, in _run_code\n",
      "    exec(code, run_globals)\n",
      "  File \"C:\\Users\\Work\\anaconda3\\Scripts\\pip.exe\\__main__.py\", line 7, in <module>\n",
      "    sys.exit(main())\n",
      "  File \"C:\\Users\\Work\\anaconda3\\lib\\site-packages\\pip\\_internal\\cli\\main.py\", line 79, in main\n",
      "    return command.main(cmd_args)\n",
      "  File \"C:\\Users\\Work\\anaconda3\\lib\\site-packages\\pip\\_internal\\cli\\base_command.py\", line 101, in main\n",
      "    return self._main(args)\n",
      "  File \"C:\\Users\\Work\\anaconda3\\lib\\site-packages\\pip\\_internal\\cli\\base_command.py\", line 223, in _main\n",
      "    return run(options, args)\n",
      "  File \"C:\\Users\\Work\\anaconda3\\lib\\site-packages\\pip\\_internal\\cli\\base_command.py\", line 169, in exc_logging_wrapper\n",
      "    status = run_func(*args)\n",
      "  File \"C:\\Users\\Work\\anaconda3\\lib\\site-packages\\pip\\_internal\\cli\\req_command.py\", line 248, in wrapper\n",
      "    return func(self, options, args)\n",
      "  File \"C:\\Users\\Work\\anaconda3\\lib\\site-packages\\pip\\_internal\\commands\\install.py\", line 377, in run\n",
      "    requirement_set = resolver.resolve(\n",
      "  File \"C:\\Users\\Work\\anaconda3\\lib\\site-packages\\pip\\_internal\\resolution\\resolvelib\\resolver.py\", line 73, in resolve\n",
      "    collected = self.factory.collect_root_requirements(root_reqs)\n",
      "  File \"C:\\Users\\Work\\anaconda3\\lib\\site-packages\\pip\\_internal\\resolution\\resolvelib\\factory.py\", line 491, in collect_root_requirements\n",
      "    req = self._make_requirement_from_install_req(\n",
      "  File \"C:\\Users\\Work\\anaconda3\\lib\\site-packages\\pip\\_internal\\resolution\\resolvelib\\factory.py\", line 453, in _make_requirement_from_install_req\n",
      "    cand = self._make_candidate_from_link(\n",
      "  File \"C:\\Users\\Work\\anaconda3\\lib\\site-packages\\pip\\_internal\\resolution\\resolvelib\\factory.py\", line 206, in _make_candidate_from_link\n",
      "    self._link_candidate_cache[link] = LinkCandidate(\n",
      "  File \"C:\\Users\\Work\\anaconda3\\lib\\site-packages\\pip\\_internal\\resolution\\resolvelib\\candidates.py\", line 293, in __init__\n",
      "    super().__init__(\n",
      "  File \"C:\\Users\\Work\\anaconda3\\lib\\site-packages\\pip\\_internal\\resolution\\resolvelib\\candidates.py\", line 156, in __init__\n",
      "    self.dist = self._prepare()\n",
      "  File \"C:\\Users\\Work\\anaconda3\\lib\\site-packages\\pip\\_internal\\resolution\\resolvelib\\candidates.py\", line 225, in _prepare\n",
      "    dist = self._prepare_distribution()\n",
      "  File \"C:\\Users\\Work\\anaconda3\\lib\\site-packages\\pip\\_internal\\resolution\\resolvelib\\candidates.py\", line 304, in _prepare_distribution\n",
      "    return preparer.prepare_linked_requirement(self._ireq, parallel_builds=True)\n",
      "  File \"C:\\Users\\Work\\anaconda3\\lib\\site-packages\\pip\\_internal\\operations\\prepare.py\", line 516, in prepare_linked_requirement\n",
      "    return self._prepare_linked_requirement(req, parallel_builds)\n",
      "  File \"C:\\Users\\Work\\anaconda3\\lib\\site-packages\\pip\\_internal\\operations\\prepare.py\", line 631, in _prepare_linked_requirement\n",
      "    dist = _get_prepared_distribution(\n",
      "  File \"C:\\Users\\Work\\anaconda3\\lib\\site-packages\\pip\\_internal\\operations\\prepare.py\", line 69, in _get_prepared_distribution\n",
      "    abstract_dist.prepare_distribution_metadata(\n",
      "  File \"C:\\Users\\Work\\anaconda3\\lib\\site-packages\\pip\\_internal\\distributions\\sdist.py\", line 38, in prepare_distribution_metadata\n",
      "    self._prepare_build_backend(finder)\n",
      "  File \"C:\\Users\\Work\\anaconda3\\lib\\site-packages\\pip\\_internal\\distributions\\sdist.py\", line 70, in _prepare_build_backend\n",
      "    self.req.build_env.install_requirements(\n",
      "  File \"C:\\Users\\Work\\anaconda3\\lib\\site-packages\\pip\\_internal\\build_env.py\", line 217, in install_requirements\n",
      "    self._install_requirements(\n",
      "  File \"C:\\Users\\Work\\anaconda3\\lib\\site-packages\\pip\\_internal\\build_env.py\", line 274, in _install_requirements\n",
      "    with open_spinner(f\"Installing {kind}\") as spinner:\n",
      "  File \"C:\\Users\\Work\\anaconda3\\lib\\contextlib.py\", line 119, in __enter__\n",
      "    return next(self.gen)\n",
      "  File \"C:\\Users\\Work\\anaconda3\\lib\\site-packages\\pip\\_internal\\cli\\spinners.py\", line 125, in open_spinner\n",
      "    spinner = NonInteractiveSpinner(message)\n",
      "  File \"C:\\Users\\Work\\anaconda3\\lib\\site-packages\\pip\\_internal\\cli\\spinners.py\", line 80, in __init__\n",
      "    self._update(\"started\")\n",
      "  File \"C:\\Users\\Work\\anaconda3\\lib\\site-packages\\pip\\_internal\\cli\\spinners.py\", line 85, in _update\n",
      "    logger.info(\"%s: %s\", self._message, status)\n",
      "  File \"C:\\Users\\Work\\anaconda3\\lib\\logging\\__init__.py\", line 1446, in info\n",
      "    self._log(INFO, msg, args, **kwargs)\n",
      "  File \"C:\\Users\\Work\\anaconda3\\lib\\logging\\__init__.py\", line 1589, in _log\n",
      "    self.handle(record)\n",
      "  File \"C:\\Users\\Work\\anaconda3\\lib\\logging\\__init__.py\", line 1599, in handle\n",
      "    self.callHandlers(record)\n",
      "  File \"C:\\Users\\Work\\anaconda3\\lib\\logging\\__init__.py\", line 1661, in callHandlers\n",
      "    hdlr.handle(record)\n",
      "  File \"C:\\Users\\Work\\anaconda3\\lib\\logging\\__init__.py\", line 952, in handle\n",
      "    self.emit(record)\n",
      "  File \"C:\\Users\\Work\\anaconda3\\lib\\site-packages\\pip\\_internal\\utils\\logging.py\", line 179, in emit\n",
      "    self.handleError(record)\n",
      "Message: '%s: %s'\n",
      "Arguments: ('Installing build dependencies', 'started')\n",
      "--- Logging error ---\n",
      "Traceback (most recent call last):\n",
      "  File \"C:\\Users\\Work\\anaconda3\\lib\\site-packages\\pip\\_internal\\utils\\logging.py\", line 177, in emit\n",
      "    self.console.print(renderable, overflow=\"ignore\", crop=False, style=style)\n",
      "  File \"C:\\Users\\Work\\anaconda3\\lib\\site-packages\\pip\\_vendor\\rich\\console.py\", line 1719, in print\n",
      "    self._buffer.extend(new_segments)\n",
      "  File \"C:\\Users\\Work\\anaconda3\\lib\\site-packages\\pip\\_vendor\\rich\\console.py\", line 864, in __exit__\n",
      "    self._exit_buffer()\n",
      "  File \"C:\\Users\\Work\\anaconda3\\lib\\site-packages\\pip\\_vendor\\rich\\console.py\", line 822, in _exit_buffer\n",
      "    self._check_buffer()\n",
      "  File \"C:\\Users\\Work\\anaconda3\\lib\\site-packages\\pip\\_vendor\\rich\\console.py\", line 2027, in _check_buffer\n",
      "    legacy_windows_render(buffer, LegacyWindowsTerm(self.file))\n",
      "  File \"C:\\Users\\Work\\anaconda3\\lib\\site-packages\\pip\\_vendor\\rich\\_windows_renderer.py\", line 19, in legacy_windows_render\n",
      "    term.write_text(text)\n",
      "  File \"C:\\Users\\Work\\anaconda3\\lib\\site-packages\\pip\\_vendor\\rich\\_win32_console.py\", line 403, in write_text\n",
      "    self.write(text)\n",
      "  File \"C:\\Users\\Work\\anaconda3\\lib\\encodings\\cp1251.py\", line 19, in encode\n",
      "    return codecs.charmap_encode(input,self.errors,encoding_table)[0]\n",
      "UnicodeEncodeError: 'charmap' codec can't encode character '\\xf6' in position 77: character maps to <undefined>\n",
      "Call stack:\n",
      "  File \"C:\\Users\\Work\\anaconda3\\lib\\runpy.py\", line 197, in _run_module_as_main\n",
      "    return _run_code(code, main_globals, None,\n",
      "  File \"C:\\Users\\Work\\anaconda3\\lib\\runpy.py\", line 87, in _run_code\n",
      "    exec(code, run_globals)\n",
      "  File \"C:\\Users\\Work\\anaconda3\\Scripts\\pip.exe\\__main__.py\", line 7, in <module>\n",
      "    sys.exit(main())\n",
      "  File \"C:\\Users\\Work\\anaconda3\\lib\\site-packages\\pip\\_internal\\cli\\main.py\", line 79, in main\n",
      "    return command.main(cmd_args)\n",
      "  File \"C:\\Users\\Work\\anaconda3\\lib\\site-packages\\pip\\_internal\\cli\\base_command.py\", line 101, in main\n",
      "    return self._main(args)\n",
      "  File \"C:\\Users\\Work\\anaconda3\\lib\\site-packages\\pip\\_internal\\cli\\base_command.py\", line 223, in _main\n",
      "    return run(options, args)\n",
      "  File \"C:\\Users\\Work\\anaconda3\\lib\\site-packages\\pip\\_internal\\cli\\base_command.py\", line 169, in exc_logging_wrapper\n",
      "    status = run_func(*args)\n",
      "  File \"C:\\Users\\Work\\anaconda3\\lib\\site-packages\\pip\\_internal\\cli\\req_command.py\", line 248, in wrapper\n",
      "    return func(self, options, args)\n",
      "  File \"C:\\Users\\Work\\anaconda3\\lib\\site-packages\\pip\\_internal\\commands\\install.py\", line 377, in run\n",
      "    requirement_set = resolver.resolve(\n",
      "  File \"C:\\Users\\Work\\anaconda3\\lib\\site-packages\\pip\\_internal\\resolution\\resolvelib\\resolver.py\", line 73, in resolve\n",
      "    collected = self.factory.collect_root_requirements(root_reqs)\n",
      "  File \"C:\\Users\\Work\\anaconda3\\lib\\site-packages\\pip\\_internal\\resolution\\resolvelib\\factory.py\", line 491, in collect_root_requirements\n",
      "    req = self._make_requirement_from_install_req(\n",
      "  File \"C:\\Users\\Work\\anaconda3\\lib\\site-packages\\pip\\_internal\\resolution\\resolvelib\\factory.py\", line 453, in _make_requirement_from_install_req\n",
      "    cand = self._make_candidate_from_link(\n",
      "  File \"C:\\Users\\Work\\anaconda3\\lib\\site-packages\\pip\\_internal\\resolution\\resolvelib\\factory.py\", line 206, in _make_candidate_from_link\n",
      "    self._link_candidate_cache[link] = LinkCandidate(\n",
      "  File \"C:\\Users\\Work\\anaconda3\\lib\\site-packages\\pip\\_internal\\resolution\\resolvelib\\candidates.py\", line 293, in __init__\n",
      "    super().__init__(\n",
      "  File \"C:\\Users\\Work\\anaconda3\\lib\\site-packages\\pip\\_internal\\resolution\\resolvelib\\candidates.py\", line 156, in __init__\n",
      "    self.dist = self._prepare()\n",
      "  File \"C:\\Users\\Work\\anaconda3\\lib\\site-packages\\pip\\_internal\\resolution\\resolvelib\\candidates.py\", line 225, in _prepare\n",
      "    dist = self._prepare_distribution()\n",
      "  File \"C:\\Users\\Work\\anaconda3\\lib\\site-packages\\pip\\_internal\\resolution\\resolvelib\\candidates.py\", line 304, in _prepare_distribution\n",
      "    return preparer.prepare_linked_requirement(self._ireq, parallel_builds=True)\n",
      "  File \"C:\\Users\\Work\\anaconda3\\lib\\site-packages\\pip\\_internal\\operations\\prepare.py\", line 516, in prepare_linked_requirement\n",
      "    return self._prepare_linked_requirement(req, parallel_builds)\n",
      "  File \"C:\\Users\\Work\\anaconda3\\lib\\site-packages\\pip\\_internal\\operations\\prepare.py\", line 631, in _prepare_linked_requirement\n",
      "    dist = _get_prepared_distribution(\n",
      "  File \"C:\\Users\\Work\\anaconda3\\lib\\site-packages\\pip\\_internal\\operations\\prepare.py\", line 69, in _get_prepared_distribution\n",
      "    abstract_dist.prepare_distribution_metadata(\n",
      "  File \"C:\\Users\\Work\\anaconda3\\lib\\site-packages\\pip\\_internal\\distributions\\sdist.py\", line 38, in prepare_distribution_metadata\n",
      "    self._prepare_build_backend(finder)\n",
      "  File \"C:\\Users\\Work\\anaconda3\\lib\\site-packages\\pip\\_internal\\distributions\\sdist.py\", line 70, in _prepare_build_backend\n",
      "    self.req.build_env.install_requirements(\n",
      "  File \"C:\\Users\\Work\\anaconda3\\lib\\site-packages\\pip\\_internal\\build_env.py\", line 217, in install_requirements\n",
      "    self._install_requirements(\n",
      "  File \"C:\\Users\\Work\\anaconda3\\lib\\site-packages\\pip\\_internal\\build_env.py\", line 275, in _install_requirements\n",
      "    call_subprocess(\n",
      "  File \"C:\\Users\\Work\\anaconda3\\lib\\site-packages\\pip\\_internal\\utils\\subprocess.py\", line 203, in call_subprocess\n",
      "    spinner.finish(\"done\")\n",
      "  File \"C:\\Users\\Work\\anaconda3\\lib\\site-packages\\pip\\_internal\\cli\\spinners.py\", line 97, in finish\n",
      "    self._update(f\"finished with status '{final_status}'\")\n",
      "  File \"C:\\Users\\Work\\anaconda3\\lib\\site-packages\\pip\\_internal\\cli\\spinners.py\", line 85, in _update\n",
      "    logger.info(\"%s: %s\", self._message, status)\n",
      "  File \"C:\\Users\\Work\\anaconda3\\lib\\logging\\__init__.py\", line 1446, in info\n",
      "    self._log(INFO, msg, args, **kwargs)\n",
      "  File \"C:\\Users\\Work\\anaconda3\\lib\\logging\\__init__.py\", line 1589, in _log\n",
      "    self.handle(record)\n",
      "  File \"C:\\Users\\Work\\anaconda3\\lib\\logging\\__init__.py\", line 1599, in handle\n",
      "    self.callHandlers(record)\n",
      "  File \"C:\\Users\\Work\\anaconda3\\lib\\logging\\__init__.py\", line 1661, in callHandlers\n",
      "    hdlr.handle(record)\n",
      "  File \"C:\\Users\\Work\\anaconda3\\lib\\logging\\__init__.py\", line 952, in handle\n",
      "    self.emit(record)\n",
      "  File \"C:\\Users\\Work\\anaconda3\\lib\\site-packages\\pip\\_internal\\utils\\logging.py\", line 179, in emit\n",
      "    self.handleError(record)\n",
      "Message: '%s: %s'\n",
      "Arguments: ('Installing build dependencies', \"finished with status 'done'\")\n",
      "--- Logging error ---\n",
      "Traceback (most recent call last):\n",
      "  File \"C:\\Users\\Work\\anaconda3\\lib\\site-packages\\pip\\_internal\\utils\\logging.py\", line 177, in emit\n",
      "    self.console.print(renderable, overflow=\"ignore\", crop=False, style=style)\n",
      "  File \"C:\\Users\\Work\\anaconda3\\lib\\site-packages\\pip\\_vendor\\rich\\console.py\", line 1719, in print\n",
      "    self._buffer.extend(new_segments)\n",
      "  File \"C:\\Users\\Work\\anaconda3\\lib\\site-packages\\pip\\_vendor\\rich\\console.py\", line 864, in __exit__\n",
      "    self._exit_buffer()\n",
      "  File \"C:\\Users\\Work\\anaconda3\\lib\\site-packages\\pip\\_vendor\\rich\\console.py\", line 822, in _exit_buffer\n",
      "    self._check_buffer()\n",
      "  File \"C:\\Users\\Work\\anaconda3\\lib\\site-packages\\pip\\_vendor\\rich\\console.py\", line 2027, in _check_buffer\n",
      "    legacy_windows_render(buffer, LegacyWindowsTerm(self.file))\n",
      "  File \"C:\\Users\\Work\\anaconda3\\lib\\site-packages\\pip\\_vendor\\rich\\_windows_renderer.py\", line 19, in legacy_windows_render\n",
      "    term.write_text(text)\n",
      "  File \"C:\\Users\\Work\\anaconda3\\lib\\site-packages\\pip\\_vendor\\rich\\_win32_console.py\", line 403, in write_text\n",
      "    self.write(text)\n",
      "  File \"C:\\Users\\Work\\anaconda3\\lib\\encodings\\cp1251.py\", line 19, in encode\n",
      "    return codecs.charmap_encode(input,self.errors,encoding_table)[0]\n",
      "UnicodeEncodeError: 'charmap' codec can't encode character '\\xf6' in position 77: character maps to <undefined>\n",
      "Call stack:\n",
      "  File \"C:\\Users\\Work\\anaconda3\\lib\\runpy.py\", line 197, in _run_module_as_main\n",
      "    return _run_code(code, main_globals, None,\n",
      "  File \"C:\\Users\\Work\\anaconda3\\lib\\runpy.py\", line 87, in _run_code\n",
      "    exec(code, run_globals)\n",
      "  File \"C:\\Users\\Work\\anaconda3\\Scripts\\pip.exe\\__main__.py\", line 7, in <module>\n",
      "    sys.exit(main())\n",
      "  File \"C:\\Users\\Work\\anaconda3\\lib\\site-packages\\pip\\_internal\\cli\\main.py\", line 79, in main\n",
      "    return command.main(cmd_args)\n",
      "  File \"C:\\Users\\Work\\anaconda3\\lib\\site-packages\\pip\\_internal\\cli\\base_command.py\", line 101, in main\n",
      "    return self._main(args)\n",
      "  File \"C:\\Users\\Work\\anaconda3\\lib\\site-packages\\pip\\_internal\\cli\\base_command.py\", line 223, in _main\n",
      "    return run(options, args)\n",
      "  File \"C:\\Users\\Work\\anaconda3\\lib\\site-packages\\pip\\_internal\\cli\\base_command.py\", line 169, in exc_logging_wrapper\n",
      "    status = run_func(*args)\n",
      "  File \"C:\\Users\\Work\\anaconda3\\lib\\site-packages\\pip\\_internal\\cli\\req_command.py\", line 248, in wrapper\n",
      "    return func(self, options, args)\n",
      "  File \"C:\\Users\\Work\\anaconda3\\lib\\site-packages\\pip\\_internal\\commands\\install.py\", line 377, in run\n",
      "    requirement_set = resolver.resolve(\n",
      "  File \"C:\\Users\\Work\\anaconda3\\lib\\site-packages\\pip\\_internal\\resolution\\resolvelib\\resolver.py\", line 73, in resolve\n",
      "    collected = self.factory.collect_root_requirements(root_reqs)\n",
      "  File \"C:\\Users\\Work\\anaconda3\\lib\\site-packages\\pip\\_internal\\resolution\\resolvelib\\factory.py\", line 491, in collect_root_requirements\n",
      "    req = self._make_requirement_from_install_req(\n",
      "  File \"C:\\Users\\Work\\anaconda3\\lib\\site-packages\\pip\\_internal\\resolution\\resolvelib\\factory.py\", line 453, in _make_requirement_from_install_req\n",
      "    cand = self._make_candidate_from_link(\n",
      "  File \"C:\\Users\\Work\\anaconda3\\lib\\site-packages\\pip\\_internal\\resolution\\resolvelib\\factory.py\", line 206, in _make_candidate_from_link\n",
      "    self._link_candidate_cache[link] = LinkCandidate(\n",
      "  File \"C:\\Users\\Work\\anaconda3\\lib\\site-packages\\pip\\_internal\\resolution\\resolvelib\\candidates.py\", line 293, in __init__\n",
      "    super().__init__(\n",
      "  File \"C:\\Users\\Work\\anaconda3\\lib\\site-packages\\pip\\_internal\\resolution\\resolvelib\\candidates.py\", line 156, in __init__\n",
      "    self.dist = self._prepare()\n",
      "  File \"C:\\Users\\Work\\anaconda3\\lib\\site-packages\\pip\\_internal\\resolution\\resolvelib\\candidates.py\", line 225, in _prepare\n",
      "    dist = self._prepare_distribution()\n",
      "  File \"C:\\Users\\Work\\anaconda3\\lib\\site-packages\\pip\\_internal\\resolution\\resolvelib\\candidates.py\", line 304, in _prepare_distribution\n",
      "    return preparer.prepare_linked_requirement(self._ireq, parallel_builds=True)\n",
      "  File \"C:\\Users\\Work\\anaconda3\\lib\\site-packages\\pip\\_internal\\operations\\prepare.py\", line 516, in prepare_linked_requirement\n",
      "    return self._prepare_linked_requirement(req, parallel_builds)\n",
      "  File \"C:\\Users\\Work\\anaconda3\\lib\\site-packages\\pip\\_internal\\operations\\prepare.py\", line 631, in _prepare_linked_requirement\n",
      "    dist = _get_prepared_distribution(\n",
      "  File \"C:\\Users\\Work\\anaconda3\\lib\\site-packages\\pip\\_internal\\operations\\prepare.py\", line 69, in _get_prepared_distribution\n",
      "    abstract_dist.prepare_distribution_metadata(\n",
      "  File \"C:\\Users\\Work\\anaconda3\\lib\\site-packages\\pip\\_internal\\distributions\\sdist.py\", line 48, in prepare_distribution_metadata\n",
      "    self._install_build_reqs(finder)\n",
      "  File \"C:\\Users\\Work\\anaconda3\\lib\\site-packages\\pip\\_internal\\distributions\\sdist.py\", line 118, in _install_build_reqs\n",
      "    build_reqs = self._get_build_requires_wheel()\n",
      "  File \"C:\\Users\\Work\\anaconda3\\lib\\site-packages\\pip\\_internal\\distributions\\sdist.py\", line 95, in _get_build_requires_wheel\n",
      "    return backend.get_requires_for_build_wheel()\n",
      "  File \"C:\\Users\\Work\\anaconda3\\lib\\site-packages\\pip\\_internal\\utils\\misc.py\", line 692, in get_requires_for_build_wheel\n",
      "    return super().get_requires_for_build_wheel(config_settings=cs)\n",
      "  File \"C:\\Users\\Work\\anaconda3\\lib\\site-packages\\pip\\_vendor\\pyproject_hooks\\_impl.py\", line 166, in get_requires_for_build_wheel\n",
      "    return self._call_hook('get_requires_for_build_wheel', {\n",
      "  File \"C:\\Users\\Work\\anaconda3\\lib\\site-packages\\pip\\_vendor\\pyproject_hooks\\_impl.py\", line 311, in _call_hook\n",
      "    self._subprocess_runner(\n",
      "  File \"C:\\Users\\Work\\anaconda3\\lib\\site-packages\\pip\\_internal\\utils\\subprocess.py\", line 251, in runner\n",
      "    with open_spinner(message) as spinner:\n",
      "  File \"C:\\Users\\Work\\anaconda3\\lib\\contextlib.py\", line 119, in __enter__\n",
      "    return next(self.gen)\n",
      "  File \"C:\\Users\\Work\\anaconda3\\lib\\site-packages\\pip\\_internal\\cli\\spinners.py\", line 125, in open_spinner\n",
      "    spinner = NonInteractiveSpinner(message)\n",
      "  File \"C:\\Users\\Work\\anaconda3\\lib\\site-packages\\pip\\_internal\\cli\\spinners.py\", line 80, in __init__\n",
      "    self._update(\"started\")\n",
      "  File \"C:\\Users\\Work\\anaconda3\\lib\\site-packages\\pip\\_internal\\cli\\spinners.py\", line 85, in _update\n",
      "    logger.info(\"%s: %s\", self._message, status)\n",
      "  File \"C:\\Users\\Work\\anaconda3\\lib\\logging\\__init__.py\", line 1446, in info\n",
      "    self._log(INFO, msg, args, **kwargs)\n",
      "  File \"C:\\Users\\Work\\anaconda3\\lib\\logging\\__init__.py\", line 1589, in _log\n",
      "    self.handle(record)\n",
      "  File \"C:\\Users\\Work\\anaconda3\\lib\\logging\\__init__.py\", line 1599, in handle\n",
      "    self.callHandlers(record)\n",
      "  File \"C:\\Users\\Work\\anaconda3\\lib\\logging\\__init__.py\", line 1661, in callHandlers\n",
      "    hdlr.handle(record)\n",
      "  File \"C:\\Users\\Work\\anaconda3\\lib\\logging\\__init__.py\", line 952, in handle\n",
      "    self.emit(record)\n",
      "  File \"C:\\Users\\Work\\anaconda3\\lib\\site-packages\\pip\\_internal\\utils\\logging.py\", line 179, in emit\n",
      "    self.handleError(record)\n",
      "Message: '%s: %s'\n",
      "Arguments: ('Getting requirements to build wheel', 'started')\n",
      "--- Logging error ---\n",
      "Traceback (most recent call last):\n",
      "  File \"C:\\Users\\Work\\anaconda3\\lib\\site-packages\\pip\\_internal\\utils\\logging.py\", line 177, in emit\n",
      "    self.console.print(renderable, overflow=\"ignore\", crop=False, style=style)\n",
      "  File \"C:\\Users\\Work\\anaconda3\\lib\\site-packages\\pip\\_vendor\\rich\\console.py\", line 1719, in print\n",
      "    self._buffer.extend(new_segments)\n",
      "  File \"C:\\Users\\Work\\anaconda3\\lib\\site-packages\\pip\\_vendor\\rich\\console.py\", line 864, in __exit__\n",
      "    self._exit_buffer()\n",
      "  File \"C:\\Users\\Work\\anaconda3\\lib\\site-packages\\pip\\_vendor\\rich\\console.py\", line 822, in _exit_buffer\n",
      "    self._check_buffer()\n",
      "  File \"C:\\Users\\Work\\anaconda3\\lib\\site-packages\\pip\\_vendor\\rich\\console.py\", line 2027, in _check_buffer\n",
      "    legacy_windows_render(buffer, LegacyWindowsTerm(self.file))\n",
      "  File \"C:\\Users\\Work\\anaconda3\\lib\\site-packages\\pip\\_vendor\\rich\\_windows_renderer.py\", line 19, in legacy_windows_render\n",
      "    term.write_text(text)\n",
      "  File \"C:\\Users\\Work\\anaconda3\\lib\\site-packages\\pip\\_vendor\\rich\\_win32_console.py\", line 403, in write_text\n",
      "    self.write(text)\n",
      "  File \"C:\\Users\\Work\\anaconda3\\lib\\encodings\\cp1251.py\", line 19, in encode\n",
      "    return codecs.charmap_encode(input,self.errors,encoding_table)[0]\n",
      "UnicodeEncodeError: 'charmap' codec can't encode character '\\xf6' in position 77: character maps to <undefined>\n",
      "Call stack:\n",
      "  File \"C:\\Users\\Work\\anaconda3\\lib\\runpy.py\", line 197, in _run_module_as_main\n",
      "    return _run_code(code, main_globals, None,\n",
      "  File \"C:\\Users\\Work\\anaconda3\\lib\\runpy.py\", line 87, in _run_code\n",
      "    exec(code, run_globals)\n",
      "  File \"C:\\Users\\Work\\anaconda3\\Scripts\\pip.exe\\__main__.py\", line 7, in <module>\n",
      "    sys.exit(main())\n",
      "  File \"C:\\Users\\Work\\anaconda3\\lib\\site-packages\\pip\\_internal\\cli\\main.py\", line 79, in main\n",
      "    return command.main(cmd_args)\n",
      "  File \"C:\\Users\\Work\\anaconda3\\lib\\site-packages\\pip\\_internal\\cli\\base_command.py\", line 101, in main\n",
      "    return self._main(args)\n",
      "  File \"C:\\Users\\Work\\anaconda3\\lib\\site-packages\\pip\\_internal\\cli\\base_command.py\", line 223, in _main\n",
      "    return run(options, args)\n",
      "  File \"C:\\Users\\Work\\anaconda3\\lib\\site-packages\\pip\\_internal\\cli\\base_command.py\", line 169, in exc_logging_wrapper\n",
      "    status = run_func(*args)\n",
      "  File \"C:\\Users\\Work\\anaconda3\\lib\\site-packages\\pip\\_internal\\cli\\req_command.py\", line 248, in wrapper\n",
      "    return func(self, options, args)\n",
      "  File \"C:\\Users\\Work\\anaconda3\\lib\\site-packages\\pip\\_internal\\commands\\install.py\", line 377, in run\n",
      "    requirement_set = resolver.resolve(\n",
      "  File \"C:\\Users\\Work\\anaconda3\\lib\\site-packages\\pip\\_internal\\resolution\\resolvelib\\resolver.py\", line 73, in resolve\n",
      "    collected = self.factory.collect_root_requirements(root_reqs)\n",
      "  File \"C:\\Users\\Work\\anaconda3\\lib\\site-packages\\pip\\_internal\\resolution\\resolvelib\\factory.py\", line 491, in collect_root_requirements\n",
      "    req = self._make_requirement_from_install_req(\n",
      "  File \"C:\\Users\\Work\\anaconda3\\lib\\site-packages\\pip\\_internal\\resolution\\resolvelib\\factory.py\", line 453, in _make_requirement_from_install_req\n",
      "    cand = self._make_candidate_from_link(\n",
      "  File \"C:\\Users\\Work\\anaconda3\\lib\\site-packages\\pip\\_internal\\resolution\\resolvelib\\factory.py\", line 206, in _make_candidate_from_link\n",
      "    self._link_candidate_cache[link] = LinkCandidate(\n",
      "  File \"C:\\Users\\Work\\anaconda3\\lib\\site-packages\\pip\\_internal\\resolution\\resolvelib\\candidates.py\", line 293, in __init__\n",
      "    super().__init__(\n",
      "  File \"C:\\Users\\Work\\anaconda3\\lib\\site-packages\\pip\\_internal\\resolution\\resolvelib\\candidates.py\", line 156, in __init__\n",
      "    self.dist = self._prepare()\n",
      "  File \"C:\\Users\\Work\\anaconda3\\lib\\site-packages\\pip\\_internal\\resolution\\resolvelib\\candidates.py\", line 225, in _prepare\n",
      "    dist = self._prepare_distribution()\n",
      "  File \"C:\\Users\\Work\\anaconda3\\lib\\site-packages\\pip\\_internal\\resolution\\resolvelib\\candidates.py\", line 304, in _prepare_distribution\n",
      "    return preparer.prepare_linked_requirement(self._ireq, parallel_builds=True)\n",
      "  File \"C:\\Users\\Work\\anaconda3\\lib\\site-packages\\pip\\_internal\\operations\\prepare.py\", line 516, in prepare_linked_requirement\n",
      "    return self._prepare_linked_requirement(req, parallel_builds)\n",
      "  File \"C:\\Users\\Work\\anaconda3\\lib\\site-packages\\pip\\_internal\\operations\\prepare.py\", line 631, in _prepare_linked_requirement\n",
      "    dist = _get_prepared_distribution(\n",
      "  File \"C:\\Users\\Work\\anaconda3\\lib\\site-packages\\pip\\_internal\\operations\\prepare.py\", line 69, in _get_prepared_distribution\n",
      "    abstract_dist.prepare_distribution_metadata(\n",
      "  File \"C:\\Users\\Work\\anaconda3\\lib\\site-packages\\pip\\_internal\\distributions\\sdist.py\", line 48, in prepare_distribution_metadata\n",
      "    self._install_build_reqs(finder)\n",
      "  File \"C:\\Users\\Work\\anaconda3\\lib\\site-packages\\pip\\_internal\\distributions\\sdist.py\", line 118, in _install_build_reqs\n",
      "    build_reqs = self._get_build_requires_wheel()\n",
      "  File \"C:\\Users\\Work\\anaconda3\\lib\\site-packages\\pip\\_internal\\distributions\\sdist.py\", line 95, in _get_build_requires_wheel\n",
      "    return backend.get_requires_for_build_wheel()\n",
      "  File \"C:\\Users\\Work\\anaconda3\\lib\\site-packages\\pip\\_internal\\utils\\misc.py\", line 692, in get_requires_for_build_wheel\n",
      "    return super().get_requires_for_build_wheel(config_settings=cs)\n",
      "  File \"C:\\Users\\Work\\anaconda3\\lib\\site-packages\\pip\\_vendor\\pyproject_hooks\\_impl.py\", line 166, in get_requires_for_build_wheel\n",
      "    return self._call_hook('get_requires_for_build_wheel', {\n",
      "  File \"C:\\Users\\Work\\anaconda3\\lib\\site-packages\\pip\\_vendor\\pyproject_hooks\\_impl.py\", line 311, in _call_hook\n",
      "    self._subprocess_runner(\n",
      "  File \"C:\\Users\\Work\\anaconda3\\lib\\site-packages\\pip\\_internal\\utils\\subprocess.py\", line 252, in runner\n",
      "    call_subprocess(\n",
      "  File \"C:\\Users\\Work\\anaconda3\\lib\\site-packages\\pip\\_internal\\utils\\subprocess.py\", line 203, in call_subprocess\n",
      "    spinner.finish(\"done\")\n",
      "  File \"C:\\Users\\Work\\anaconda3\\lib\\site-packages\\pip\\_internal\\cli\\spinners.py\", line 97, in finish\n",
      "    self._update(f\"finished with status '{final_status}'\")\n",
      "  File \"C:\\Users\\Work\\anaconda3\\lib\\site-packages\\pip\\_internal\\cli\\spinners.py\", line 85, in _update\n",
      "    logger.info(\"%s: %s\", self._message, status)\n",
      "  File \"C:\\Users\\Work\\anaconda3\\lib\\logging\\__init__.py\", line 1446, in info\n",
      "    self._log(INFO, msg, args, **kwargs)\n",
      "  File \"C:\\Users\\Work\\anaconda3\\lib\\logging\\__init__.py\", line 1589, in _log\n",
      "    self.handle(record)\n",
      "  File \"C:\\Users\\Work\\anaconda3\\lib\\logging\\__init__.py\", line 1599, in handle\n",
      "    self.callHandlers(record)\n",
      "  File \"C:\\Users\\Work\\anaconda3\\lib\\logging\\__init__.py\", line 1661, in callHandlers\n",
      "    hdlr.handle(record)\n",
      "  File \"C:\\Users\\Work\\anaconda3\\lib\\logging\\__init__.py\", line 952, in handle\n",
      "    self.emit(record)\n",
      "  File \"C:\\Users\\Work\\anaconda3\\lib\\site-packages\\pip\\_internal\\utils\\logging.py\", line 179, in emit\n",
      "    self.handleError(record)\n",
      "Message: '%s: %s'\n",
      "Arguments: ('Getting requirements to build wheel', \"finished with status 'done'\")\n",
      "--- Logging error ---\n",
      "Traceback (most recent call last):\n",
      "  File \"C:\\Users\\Work\\anaconda3\\lib\\site-packages\\pip\\_internal\\utils\\logging.py\", line 177, in emit\n",
      "    self.console.print(renderable, overflow=\"ignore\", crop=False, style=style)\n",
      "  File \"C:\\Users\\Work\\anaconda3\\lib\\site-packages\\pip\\_vendor\\rich\\console.py\", line 1719, in print\n",
      "    self._buffer.extend(new_segments)\n",
      "  File \"C:\\Users\\Work\\anaconda3\\lib\\site-packages\\pip\\_vendor\\rich\\console.py\", line 864, in __exit__\n",
      "    self._exit_buffer()\n",
      "  File \"C:\\Users\\Work\\anaconda3\\lib\\site-packages\\pip\\_vendor\\rich\\console.py\", line 822, in _exit_buffer\n",
      "    self._check_buffer()\n",
      "  File \"C:\\Users\\Work\\anaconda3\\lib\\site-packages\\pip\\_vendor\\rich\\console.py\", line 2027, in _check_buffer\n",
      "    legacy_windows_render(buffer, LegacyWindowsTerm(self.file))\n",
      "  File \"C:\\Users\\Work\\anaconda3\\lib\\site-packages\\pip\\_vendor\\rich\\_windows_renderer.py\", line 19, in legacy_windows_render\n",
      "    term.write_text(text)\n",
      "  File \"C:\\Users\\Work\\anaconda3\\lib\\site-packages\\pip\\_vendor\\rich\\_win32_console.py\", line 403, in write_text\n",
      "    self.write(text)\n",
      "  File \"C:\\Users\\Work\\anaconda3\\lib\\encodings\\cp1251.py\", line 19, in encode\n",
      "    return codecs.charmap_encode(input,self.errors,encoding_table)[0]\n",
      "UnicodeEncodeError: 'charmap' codec can't encode character '\\xf6' in position 77: character maps to <undefined>\n",
      "Call stack:\n",
      "  File \"C:\\Users\\Work\\anaconda3\\lib\\runpy.py\", line 197, in _run_module_as_main\n",
      "    return _run_code(code, main_globals, None,\n",
      "  File \"C:\\Users\\Work\\anaconda3\\lib\\runpy.py\", line 87, in _run_code\n",
      "    exec(code, run_globals)\n",
      "  File \"C:\\Users\\Work\\anaconda3\\Scripts\\pip.exe\\__main__.py\", line 7, in <module>\n",
      "    sys.exit(main())\n",
      "  File \"C:\\Users\\Work\\anaconda3\\lib\\site-packages\\pip\\_internal\\cli\\main.py\", line 79, in main\n",
      "    return command.main(cmd_args)\n",
      "  File \"C:\\Users\\Work\\anaconda3\\lib\\site-packages\\pip\\_internal\\cli\\base_command.py\", line 101, in main\n",
      "    return self._main(args)\n",
      "  File \"C:\\Users\\Work\\anaconda3\\lib\\site-packages\\pip\\_internal\\cli\\base_command.py\", line 223, in _main\n",
      "    return run(options, args)\n",
      "  File \"C:\\Users\\Work\\anaconda3\\lib\\site-packages\\pip\\_internal\\cli\\base_command.py\", line 169, in exc_logging_wrapper\n",
      "    status = run_func(*args)\n",
      "  File \"C:\\Users\\Work\\anaconda3\\lib\\site-packages\\pip\\_internal\\cli\\req_command.py\", line 248, in wrapper\n",
      "    return func(self, options, args)\n",
      "  File \"C:\\Users\\Work\\anaconda3\\lib\\site-packages\\pip\\_internal\\commands\\install.py\", line 377, in run\n",
      "    requirement_set = resolver.resolve(\n",
      "  File \"C:\\Users\\Work\\anaconda3\\lib\\site-packages\\pip\\_internal\\resolution\\resolvelib\\resolver.py\", line 73, in resolve\n",
      "    collected = self.factory.collect_root_requirements(root_reqs)\n",
      "  File \"C:\\Users\\Work\\anaconda3\\lib\\site-packages\\pip\\_internal\\resolution\\resolvelib\\factory.py\", line 491, in collect_root_requirements\n",
      "    req = self._make_requirement_from_install_req(\n",
      "  File \"C:\\Users\\Work\\anaconda3\\lib\\site-packages\\pip\\_internal\\resolution\\resolvelib\\factory.py\", line 453, in _make_requirement_from_install_req\n",
      "    cand = self._make_candidate_from_link(\n",
      "  File \"C:\\Users\\Work\\anaconda3\\lib\\site-packages\\pip\\_internal\\resolution\\resolvelib\\factory.py\", line 206, in _make_candidate_from_link\n",
      "    self._link_candidate_cache[link] = LinkCandidate(\n",
      "  File \"C:\\Users\\Work\\anaconda3\\lib\\site-packages\\pip\\_internal\\resolution\\resolvelib\\candidates.py\", line 293, in __init__\n",
      "    super().__init__(\n",
      "  File \"C:\\Users\\Work\\anaconda3\\lib\\site-packages\\pip\\_internal\\resolution\\resolvelib\\candidates.py\", line 156, in __init__\n",
      "    self.dist = self._prepare()\n",
      "  File \"C:\\Users\\Work\\anaconda3\\lib\\site-packages\\pip\\_internal\\resolution\\resolvelib\\candidates.py\", line 225, in _prepare\n",
      "    dist = self._prepare_distribution()\n",
      "  File \"C:\\Users\\Work\\anaconda3\\lib\\site-packages\\pip\\_internal\\resolution\\resolvelib\\candidates.py\", line 304, in _prepare_distribution\n",
      "    return preparer.prepare_linked_requirement(self._ireq, parallel_builds=True)\n",
      "  File \"C:\\Users\\Work\\anaconda3\\lib\\site-packages\\pip\\_internal\\operations\\prepare.py\", line 516, in prepare_linked_requirement\n",
      "    return self._prepare_linked_requirement(req, parallel_builds)\n",
      "  File \"C:\\Users\\Work\\anaconda3\\lib\\site-packages\\pip\\_internal\\operations\\prepare.py\", line 631, in _prepare_linked_requirement\n",
      "    dist = _get_prepared_distribution(\n",
      "  File \"C:\\Users\\Work\\anaconda3\\lib\\site-packages\\pip\\_internal\\operations\\prepare.py\", line 69, in _get_prepared_distribution\n",
      "    abstract_dist.prepare_distribution_metadata(\n",
      "  File \"C:\\Users\\Work\\anaconda3\\lib\\site-packages\\pip\\_internal\\distributions\\sdist.py\", line 61, in prepare_distribution_metadata\n",
      "    self.req.prepare_metadata()\n",
      "  File \"C:\\Users\\Work\\anaconda3\\lib\\site-packages\\pip\\_internal\\req\\req_install.py\", line 555, in prepare_metadata\n",
      "    self.metadata_directory = generate_metadata(\n",
      "  File \"C:\\Users\\Work\\anaconda3\\lib\\site-packages\\pip\\_internal\\operations\\build\\metadata.py\", line 35, in generate_metadata\n",
      "    distinfo_dir = backend.prepare_metadata_for_build_wheel(metadata_dir)\n",
      "  File \"C:\\Users\\Work\\anaconda3\\lib\\site-packages\\pip\\_internal\\utils\\misc.py\", line 713, in prepare_metadata_for_build_wheel\n",
      "    return super().prepare_metadata_for_build_wheel(\n",
      "  File \"C:\\Users\\Work\\anaconda3\\lib\\site-packages\\pip\\_vendor\\pyproject_hooks\\_impl.py\", line 186, in prepare_metadata_for_build_wheel\n",
      "    return self._call_hook('prepare_metadata_for_build_wheel', {\n",
      "  File \"C:\\Users\\Work\\anaconda3\\lib\\site-packages\\pip\\_vendor\\pyproject_hooks\\_impl.py\", line 311, in _call_hook\n",
      "    self._subprocess_runner(\n",
      "  File \"C:\\Users\\Work\\anaconda3\\lib\\site-packages\\pip\\_internal\\utils\\subprocess.py\", line 251, in runner\n",
      "    with open_spinner(message) as spinner:\n",
      "  File \"C:\\Users\\Work\\anaconda3\\lib\\contextlib.py\", line 119, in __enter__\n",
      "    return next(self.gen)\n",
      "  File \"C:\\Users\\Work\\anaconda3\\lib\\site-packages\\pip\\_internal\\cli\\spinners.py\", line 125, in open_spinner\n",
      "    spinner = NonInteractiveSpinner(message)\n",
      "  File \"C:\\Users\\Work\\anaconda3\\lib\\site-packages\\pip\\_internal\\cli\\spinners.py\", line 80, in __init__\n",
      "    self._update(\"started\")\n",
      "  File \"C:\\Users\\Work\\anaconda3\\lib\\site-packages\\pip\\_internal\\cli\\spinners.py\", line 85, in _update\n",
      "    logger.info(\"%s: %s\", self._message, status)\n",
      "  File \"C:\\Users\\Work\\anaconda3\\lib\\logging\\__init__.py\", line 1446, in info\n",
      "    self._log(INFO, msg, args, **kwargs)\n",
      "  File \"C:\\Users\\Work\\anaconda3\\lib\\logging\\__init__.py\", line 1589, in _log\n",
      "    self.handle(record)\n",
      "  File \"C:\\Users\\Work\\anaconda3\\lib\\logging\\__init__.py\", line 1599, in handle\n",
      "    self.callHandlers(record)\n",
      "  File \"C:\\Users\\Work\\anaconda3\\lib\\logging\\__init__.py\", line 1661, in callHandlers\n",
      "    hdlr.handle(record)\n",
      "  File \"C:\\Users\\Work\\anaconda3\\lib\\logging\\__init__.py\", line 952, in handle\n",
      "    self.emit(record)\n",
      "  File \"C:\\Users\\Work\\anaconda3\\lib\\site-packages\\pip\\_internal\\utils\\logging.py\", line 179, in emit\n",
      "    self.handleError(record)\n",
      "Message: '%s: %s'\n",
      "Arguments: ('Preparing metadata (pyproject.toml)', 'started')\n",
      "--- Logging error ---\n",
      "Traceback (most recent call last):\n",
      "  File \"C:\\Users\\Work\\anaconda3\\lib\\site-packages\\pip\\_internal\\utils\\logging.py\", line 177, in emit\n",
      "    self.console.print(renderable, overflow=\"ignore\", crop=False, style=style)\n",
      "  File \"C:\\Users\\Work\\anaconda3\\lib\\site-packages\\pip\\_vendor\\rich\\console.py\", line 1719, in print\n",
      "    self._buffer.extend(new_segments)\n",
      "  File \"C:\\Users\\Work\\anaconda3\\lib\\site-packages\\pip\\_vendor\\rich\\console.py\", line 864, in __exit__\n",
      "    self._exit_buffer()\n",
      "  File \"C:\\Users\\Work\\anaconda3\\lib\\site-packages\\pip\\_vendor\\rich\\console.py\", line 822, in _exit_buffer\n",
      "    self._check_buffer()\n",
      "  File \"C:\\Users\\Work\\anaconda3\\lib\\site-packages\\pip\\_vendor\\rich\\console.py\", line 2027, in _check_buffer\n",
      "    legacy_windows_render(buffer, LegacyWindowsTerm(self.file))\n",
      "  File \"C:\\Users\\Work\\anaconda3\\lib\\site-packages\\pip\\_vendor\\rich\\_windows_renderer.py\", line 19, in legacy_windows_render\n",
      "    term.write_text(text)\n",
      "  File \"C:\\Users\\Work\\anaconda3\\lib\\site-packages\\pip\\_vendor\\rich\\_win32_console.py\", line 403, in write_text\n",
      "    self.write(text)\n",
      "  File \"C:\\Users\\Work\\anaconda3\\lib\\encodings\\cp1251.py\", line 19, in encode\n",
      "    return codecs.charmap_encode(input,self.errors,encoding_table)[0]\n",
      "UnicodeEncodeError: 'charmap' codec can't encode character '\\xf6' in position 77: character maps to <undefined>\n",
      "Call stack:\n",
      "  File \"C:\\Users\\Work\\anaconda3\\lib\\runpy.py\", line 197, in _run_module_as_main\n",
      "    return _run_code(code, main_globals, None,\n",
      "  File \"C:\\Users\\Work\\anaconda3\\lib\\runpy.py\", line 87, in _run_code\n",
      "    exec(code, run_globals)\n",
      "  File \"C:\\Users\\Work\\anaconda3\\Scripts\\pip.exe\\__main__.py\", line 7, in <module>\n",
      "    sys.exit(main())\n",
      "  File \"C:\\Users\\Work\\anaconda3\\lib\\site-packages\\pip\\_internal\\cli\\main.py\", line 79, in main\n",
      "    return command.main(cmd_args)\n",
      "  File \"C:\\Users\\Work\\anaconda3\\lib\\site-packages\\pip\\_internal\\cli\\base_command.py\", line 101, in main\n",
      "    return self._main(args)\n",
      "  File \"C:\\Users\\Work\\anaconda3\\lib\\site-packages\\pip\\_internal\\cli\\base_command.py\", line 223, in _main\n",
      "    return run(options, args)\n",
      "  File \"C:\\Users\\Work\\anaconda3\\lib\\site-packages\\pip\\_internal\\cli\\base_command.py\", line 169, in exc_logging_wrapper\n",
      "    status = run_func(*args)\n",
      "  File \"C:\\Users\\Work\\anaconda3\\lib\\site-packages\\pip\\_internal\\cli\\req_command.py\", line 248, in wrapper\n",
      "    return func(self, options, args)\n",
      "  File \"C:\\Users\\Work\\anaconda3\\lib\\site-packages\\pip\\_internal\\commands\\install.py\", line 377, in run\n",
      "    requirement_set = resolver.resolve(\n",
      "  File \"C:\\Users\\Work\\anaconda3\\lib\\site-packages\\pip\\_internal\\resolution\\resolvelib\\resolver.py\", line 73, in resolve\n",
      "    collected = self.factory.collect_root_requirements(root_reqs)\n",
      "  File \"C:\\Users\\Work\\anaconda3\\lib\\site-packages\\pip\\_internal\\resolution\\resolvelib\\factory.py\", line 491, in collect_root_requirements\n",
      "    req = self._make_requirement_from_install_req(\n",
      "  File \"C:\\Users\\Work\\anaconda3\\lib\\site-packages\\pip\\_internal\\resolution\\resolvelib\\factory.py\", line 453, in _make_requirement_from_install_req\n",
      "    cand = self._make_candidate_from_link(\n",
      "  File \"C:\\Users\\Work\\anaconda3\\lib\\site-packages\\pip\\_internal\\resolution\\resolvelib\\factory.py\", line 206, in _make_candidate_from_link\n",
      "    self._link_candidate_cache[link] = LinkCandidate(\n",
      "  File \"C:\\Users\\Work\\anaconda3\\lib\\site-packages\\pip\\_internal\\resolution\\resolvelib\\candidates.py\", line 293, in __init__\n",
      "    super().__init__(\n",
      "  File \"C:\\Users\\Work\\anaconda3\\lib\\site-packages\\pip\\_internal\\resolution\\resolvelib\\candidates.py\", line 156, in __init__\n",
      "    self.dist = self._prepare()\n",
      "  File \"C:\\Users\\Work\\anaconda3\\lib\\site-packages\\pip\\_internal\\resolution\\resolvelib\\candidates.py\", line 225, in _prepare\n",
      "    dist = self._prepare_distribution()\n",
      "  File \"C:\\Users\\Work\\anaconda3\\lib\\site-packages\\pip\\_internal\\resolution\\resolvelib\\candidates.py\", line 304, in _prepare_distribution\n",
      "    return preparer.prepare_linked_requirement(self._ireq, parallel_builds=True)\n",
      "  File \"C:\\Users\\Work\\anaconda3\\lib\\site-packages\\pip\\_internal\\operations\\prepare.py\", line 516, in prepare_linked_requirement\n",
      "    return self._prepare_linked_requirement(req, parallel_builds)\n",
      "  File \"C:\\Users\\Work\\anaconda3\\lib\\site-packages\\pip\\_internal\\operations\\prepare.py\", line 631, in _prepare_linked_requirement\n",
      "    dist = _get_prepared_distribution(\n",
      "  File \"C:\\Users\\Work\\anaconda3\\lib\\site-packages\\pip\\_internal\\operations\\prepare.py\", line 69, in _get_prepared_distribution\n",
      "    abstract_dist.prepare_distribution_metadata(\n",
      "  File \"C:\\Users\\Work\\anaconda3\\lib\\site-packages\\pip\\_internal\\distributions\\sdist.py\", line 61, in prepare_distribution_metadata\n",
      "    self.req.prepare_metadata()\n",
      "  File \"C:\\Users\\Work\\anaconda3\\lib\\site-packages\\pip\\_internal\\req\\req_install.py\", line 555, in prepare_metadata\n",
      "    self.metadata_directory = generate_metadata(\n",
      "  File \"C:\\Users\\Work\\anaconda3\\lib\\site-packages\\pip\\_internal\\operations\\build\\metadata.py\", line 35, in generate_metadata\n",
      "    distinfo_dir = backend.prepare_metadata_for_build_wheel(metadata_dir)\n",
      "  File \"C:\\Users\\Work\\anaconda3\\lib\\site-packages\\pip\\_internal\\utils\\misc.py\", line 713, in prepare_metadata_for_build_wheel\n",
      "    return super().prepare_metadata_for_build_wheel(\n",
      "  File \"C:\\Users\\Work\\anaconda3\\lib\\site-packages\\pip\\_vendor\\pyproject_hooks\\_impl.py\", line 186, in prepare_metadata_for_build_wheel\n",
      "    return self._call_hook('prepare_metadata_for_build_wheel', {\n",
      "  File \"C:\\Users\\Work\\anaconda3\\lib\\site-packages\\pip\\_vendor\\pyproject_hooks\\_impl.py\", line 311, in _call_hook\n",
      "    self._subprocess_runner(\n",
      "  File \"C:\\Users\\Work\\anaconda3\\lib\\site-packages\\pip\\_internal\\utils\\subprocess.py\", line 252, in runner\n",
      "    call_subprocess(\n",
      "  File \"C:\\Users\\Work\\anaconda3\\lib\\site-packages\\pip\\_internal\\utils\\subprocess.py\", line 203, in call_subprocess\n",
      "    spinner.finish(\"done\")\n",
      "  File \"C:\\Users\\Work\\anaconda3\\lib\\site-packages\\pip\\_internal\\cli\\spinners.py\", line 97, in finish\n",
      "    self._update(f\"finished with status '{final_status}'\")\n",
      "  File \"C:\\Users\\Work\\anaconda3\\lib\\site-packages\\pip\\_internal\\cli\\spinners.py\", line 85, in _update\n",
      "    logger.info(\"%s: %s\", self._message, status)\n",
      "  File \"C:\\Users\\Work\\anaconda3\\lib\\logging\\__init__.py\", line 1446, in info\n",
      "    self._log(INFO, msg, args, **kwargs)\n",
      "  File \"C:\\Users\\Work\\anaconda3\\lib\\logging\\__init__.py\", line 1589, in _log\n",
      "    self.handle(record)\n",
      "  File \"C:\\Users\\Work\\anaconda3\\lib\\logging\\__init__.py\", line 1599, in handle\n",
      "    self.callHandlers(record)\n",
      "  File \"C:\\Users\\Work\\anaconda3\\lib\\logging\\__init__.py\", line 1661, in callHandlers\n",
      "    hdlr.handle(record)\n",
      "  File \"C:\\Users\\Work\\anaconda3\\lib\\logging\\__init__.py\", line 952, in handle\n",
      "    self.emit(record)\n",
      "  File \"C:\\Users\\Work\\anaconda3\\lib\\site-packages\\pip\\_internal\\utils\\logging.py\", line 179, in emit\n",
      "    self.handleError(record)\n",
      "Message: '%s: %s'\n",
      "Arguments: ('Preparing metadata (pyproject.toml)', \"finished with status 'done'\")\n",
      "--- Logging error ---\n",
      "Traceback (most recent call last):\n",
      "  File \"C:\\Users\\Work\\anaconda3\\lib\\site-packages\\pip\\_internal\\resolution\\resolvelib\\factory.py\", line 158, in _make_candidate_from_dist\n",
      "    base = self._installed_candidate_cache[dist.canonical_name]\n",
      "KeyError: 'requests'\n",
      "\n",
      "During handling of the above exception, another exception occurred:\n",
      "\n",
      "Traceback (most recent call last):\n",
      "  File \"C:\\Users\\Work\\anaconda3\\lib\\site-packages\\pip\\_internal\\utils\\logging.py\", line 177, in emit\n",
      "    self.console.print(renderable, overflow=\"ignore\", crop=False, style=style)\n",
      "  File \"C:\\Users\\Work\\anaconda3\\lib\\site-packages\\pip\\_vendor\\rich\\console.py\", line 1719, in print\n",
      "    self._buffer.extend(new_segments)\n",
      "  File \"C:\\Users\\Work\\anaconda3\\lib\\site-packages\\pip\\_vendor\\rich\\console.py\", line 864, in __exit__\n",
      "    self._exit_buffer()\n",
      "  File \"C:\\Users\\Work\\anaconda3\\lib\\site-packages\\pip\\_vendor\\rich\\console.py\", line 822, in _exit_buffer\n",
      "    self._check_buffer()\n",
      "  File \"C:\\Users\\Work\\anaconda3\\lib\\site-packages\\pip\\_vendor\\rich\\console.py\", line 2027, in _check_buffer\n",
      "    legacy_windows_render(buffer, LegacyWindowsTerm(self.file))\n",
      "  File \"C:\\Users\\Work\\anaconda3\\lib\\site-packages\\pip\\_vendor\\rich\\_windows_renderer.py\", line 19, in legacy_windows_render\n",
      "    term.write_text(text)\n",
      "  File \"C:\\Users\\Work\\anaconda3\\lib\\site-packages\\pip\\_vendor\\rich\\_win32_console.py\", line 403, in write_text\n",
      "    self.write(text)\n",
      "  File \"C:\\Users\\Work\\anaconda3\\lib\\encodings\\cp1251.py\", line 19, in encode\n",
      "    return codecs.charmap_encode(input,self.errors,encoding_table)[0]\n",
      "UnicodeEncodeError: 'charmap' codec can't encode character '\\xf6' in position 77: character maps to <undefined>\n",
      "Call stack:\n",
      "  File \"C:\\Users\\Work\\anaconda3\\lib\\runpy.py\", line 197, in _run_module_as_main\n",
      "    return _run_code(code, main_globals, None,\n",
      "  File \"C:\\Users\\Work\\anaconda3\\lib\\runpy.py\", line 87, in _run_code\n",
      "    exec(code, run_globals)\n",
      "  File \"C:\\Users\\Work\\anaconda3\\Scripts\\pip.exe\\__main__.py\", line 7, in <module>\n",
      "    sys.exit(main())\n",
      "  File \"C:\\Users\\Work\\anaconda3\\lib\\site-packages\\pip\\_internal\\cli\\main.py\", line 79, in main\n",
      "    return command.main(cmd_args)\n",
      "  File \"C:\\Users\\Work\\anaconda3\\lib\\site-packages\\pip\\_internal\\cli\\base_command.py\", line 101, in main\n",
      "    return self._main(args)\n",
      "  File \"C:\\Users\\Work\\anaconda3\\lib\\site-packages\\pip\\_internal\\cli\\base_command.py\", line 223, in _main\n",
      "    return run(options, args)\n",
      "  File \"C:\\Users\\Work\\anaconda3\\lib\\site-packages\\pip\\_internal\\cli\\base_command.py\", line 169, in exc_logging_wrapper\n",
      "    status = run_func(*args)\n",
      "  File \"C:\\Users\\Work\\anaconda3\\lib\\site-packages\\pip\\_internal\\cli\\req_command.py\", line 248, in wrapper\n",
      "    return func(self, options, args)\n",
      "  File \"C:\\Users\\Work\\anaconda3\\lib\\site-packages\\pip\\_internal\\commands\\install.py\", line 377, in run\n",
      "    requirement_set = resolver.resolve(\n",
      "  File \"C:\\Users\\Work\\anaconda3\\lib\\site-packages\\pip\\_internal\\resolution\\resolvelib\\resolver.py\", line 92, in resolve\n",
      "    result = self._result = resolver.resolve(\n",
      "  File \"C:\\Users\\Work\\anaconda3\\lib\\site-packages\\pip\\_vendor\\resolvelib\\resolvers.py\", line 546, in resolve\n",
      "    state = resolution.resolve(requirements, max_rounds=max_rounds)\n",
      "  File \"C:\\Users\\Work\\anaconda3\\lib\\site-packages\\pip\\_vendor\\resolvelib\\resolvers.py\", line 427, in resolve\n",
      "    failure_causes = self._attempt_to_pin_criterion(name)\n",
      "  File \"C:\\Users\\Work\\anaconda3\\lib\\site-packages\\pip\\_vendor\\resolvelib\\resolvers.py\", line 239, in _attempt_to_pin_criterion\n",
      "    criteria = self._get_updated_criteria(candidate)\n",
      "  File \"C:\\Users\\Work\\anaconda3\\lib\\site-packages\\pip\\_vendor\\resolvelib\\resolvers.py\", line 230, in _get_updated_criteria\n",
      "    self._add_to_criteria(criteria, requirement, parent=candidate)\n",
      "  File \"C:\\Users\\Work\\anaconda3\\lib\\site-packages\\pip\\_vendor\\resolvelib\\resolvers.py\", line 148, in _add_to_criteria\n",
      "    matches = self._p.find_matches(\n",
      "  File \"C:\\Users\\Work\\anaconda3\\lib\\site-packages\\pip\\_internal\\resolution\\resolvelib\\provider.py\", line 231, in find_matches\n",
      "    return self._factory.find_candidates(\n",
      "  File \"C:\\Users\\Work\\anaconda3\\lib\\site-packages\\pip\\_internal\\resolution\\resolvelib\\factory.py\", line 424, in find_candidates\n",
      "    return self._iter_found_candidates(\n",
      "  File \"C:\\Users\\Work\\anaconda3\\lib\\site-packages\\pip\\_internal\\resolution\\resolvelib\\factory.py\", line 320, in _iter_found_candidates\n",
      "    _get_installed_candidate(),\n",
      "  File \"C:\\Users\\Work\\anaconda3\\lib\\site-packages\\pip\\_internal\\resolution\\resolvelib\\factory.py\", line 268, in _get_installed_candidate\n",
      "    candidate = self._make_candidate_from_dist(\n",
      "  File \"C:\\Users\\Work\\anaconda3\\lib\\site-packages\\pip\\_internal\\resolution\\resolvelib\\factory.py\", line 160, in _make_candidate_from_dist\n",
      "    base = AlreadyInstalledCandidate(dist, template, factory=self)\n",
      "  File \"C:\\Users\\Work\\anaconda3\\lib\\site-packages\\pip\\_internal\\resolution\\resolvelib\\candidates.py\", line 350, in __init__\n",
      "    factory.preparer.prepare_installed_requirement(self._ireq, skip_reason)\n",
      "  File \"C:\\Users\\Work\\anaconda3\\lib\\site-packages\\pip\\_internal\\operations\\prepare.py\", line 710, in prepare_installed_requirement\n",
      "    logger.info(\n",
      "  File \"C:\\Users\\Work\\anaconda3\\lib\\logging\\__init__.py\", line 1446, in info\n",
      "    self._log(INFO, msg, args, **kwargs)\n",
      "  File \"C:\\Users\\Work\\anaconda3\\lib\\logging\\__init__.py\", line 1589, in _log\n",
      "    self.handle(record)\n",
      "  File \"C:\\Users\\Work\\anaconda3\\lib\\logging\\__init__.py\", line 1599, in handle\n",
      "    self.callHandlers(record)\n",
      "  File \"C:\\Users\\Work\\anaconda3\\lib\\logging\\__init__.py\", line 1661, in callHandlers\n",
      "    hdlr.handle(record)\n",
      "  File \"C:\\Users\\Work\\anaconda3\\lib\\logging\\__init__.py\", line 952, in handle\n",
      "    self.emit(record)\n",
      "  File \"C:\\Users\\Work\\anaconda3\\lib\\site-packages\\pip\\_internal\\utils\\logging.py\", line 179, in emit\n",
      "    self.handleError(record)\n",
      "Message: 'Requirement %s: %s (%s)'\n",
      "Arguments: ('already satisfied', <InstallRequirement object: requests in c:\\users\\work\\anaconda3\\lib\\site-packages (from Password-package==1.0.0) editable=False>, <Version('2.28.1')>)\n",
      "--- Logging error ---\n",
      "Traceback (most recent call last):\n",
      "  File \"C:\\Users\\Work\\anaconda3\\lib\\site-packages\\pip\\_internal\\resolution\\resolvelib\\factory.py\", line 158, in _make_candidate_from_dist\n",
      "    base = self._installed_candidate_cache[dist.canonical_name]\n",
      "KeyError: 'charset-normalizer'\n",
      "\n",
      "During handling of the above exception, another exception occurred:\n",
      "\n",
      "Traceback (most recent call last):\n",
      "  File \"C:\\Users\\Work\\anaconda3\\lib\\site-packages\\pip\\_internal\\utils\\logging.py\", line 177, in emit\n",
      "    self.console.print(renderable, overflow=\"ignore\", crop=False, style=style)\n",
      "  File \"C:\\Users\\Work\\anaconda3\\lib\\site-packages\\pip\\_vendor\\rich\\console.py\", line 1719, in print\n",
      "    self._buffer.extend(new_segments)\n",
      "  File \"C:\\Users\\Work\\anaconda3\\lib\\site-packages\\pip\\_vendor\\rich\\console.py\", line 864, in __exit__\n",
      "    self._exit_buffer()\n",
      "  File \"C:\\Users\\Work\\anaconda3\\lib\\site-packages\\pip\\_vendor\\rich\\console.py\", line 822, in _exit_buffer\n",
      "    self._check_buffer()\n",
      "  File \"C:\\Users\\Work\\anaconda3\\lib\\site-packages\\pip\\_vendor\\rich\\console.py\", line 2027, in _check_buffer\n",
      "    legacy_windows_render(buffer, LegacyWindowsTerm(self.file))\n",
      "  File \"C:\\Users\\Work\\anaconda3\\lib\\site-packages\\pip\\_vendor\\rich\\_windows_renderer.py\", line 19, in legacy_windows_render\n",
      "    term.write_text(text)\n",
      "  File \"C:\\Users\\Work\\anaconda3\\lib\\site-packages\\pip\\_vendor\\rich\\_win32_console.py\", line 403, in write_text\n",
      "    self.write(text)\n",
      "  File \"C:\\Users\\Work\\anaconda3\\lib\\encodings\\cp1251.py\", line 19, in encode\n",
      "    return codecs.charmap_encode(input,self.errors,encoding_table)[0]\n",
      "UnicodeEncodeError: 'charmap' codec can't encode character '\\xf6' in position 77: character maps to <undefined>\n",
      "Call stack:\n",
      "  File \"C:\\Users\\Work\\anaconda3\\lib\\runpy.py\", line 197, in _run_module_as_main\n",
      "    return _run_code(code, main_globals, None,\n",
      "  File \"C:\\Users\\Work\\anaconda3\\lib\\runpy.py\", line 87, in _run_code\n",
      "    exec(code, run_globals)\n",
      "  File \"C:\\Users\\Work\\anaconda3\\Scripts\\pip.exe\\__main__.py\", line 7, in <module>\n",
      "    sys.exit(main())\n",
      "  File \"C:\\Users\\Work\\anaconda3\\lib\\site-packages\\pip\\_internal\\cli\\main.py\", line 79, in main\n",
      "    return command.main(cmd_args)\n",
      "  File \"C:\\Users\\Work\\anaconda3\\lib\\site-packages\\pip\\_internal\\cli\\base_command.py\", line 101, in main\n",
      "    return self._main(args)\n",
      "  File \"C:\\Users\\Work\\anaconda3\\lib\\site-packages\\pip\\_internal\\cli\\base_command.py\", line 223, in _main\n",
      "    return run(options, args)\n",
      "  File \"C:\\Users\\Work\\anaconda3\\lib\\site-packages\\pip\\_internal\\cli\\base_command.py\", line 169, in exc_logging_wrapper\n",
      "    status = run_func(*args)\n",
      "  File \"C:\\Users\\Work\\anaconda3\\lib\\site-packages\\pip\\_internal\\cli\\req_command.py\", line 248, in wrapper\n",
      "    return func(self, options, args)\n",
      "  File \"C:\\Users\\Work\\anaconda3\\lib\\site-packages\\pip\\_internal\\commands\\install.py\", line 377, in run\n",
      "    requirement_set = resolver.resolve(\n",
      "  File \"C:\\Users\\Work\\anaconda3\\lib\\site-packages\\pip\\_internal\\resolution\\resolvelib\\resolver.py\", line 92, in resolve\n",
      "    result = self._result = resolver.resolve(\n",
      "  File \"C:\\Users\\Work\\anaconda3\\lib\\site-packages\\pip\\_vendor\\resolvelib\\resolvers.py\", line 546, in resolve\n",
      "    state = resolution.resolve(requirements, max_rounds=max_rounds)\n",
      "  File \"C:\\Users\\Work\\anaconda3\\lib\\site-packages\\pip\\_vendor\\resolvelib\\resolvers.py\", line 427, in resolve\n",
      "    failure_causes = self._attempt_to_pin_criterion(name)\n",
      "  File \"C:\\Users\\Work\\anaconda3\\lib\\site-packages\\pip\\_vendor\\resolvelib\\resolvers.py\", line 239, in _attempt_to_pin_criterion\n",
      "    criteria = self._get_updated_criteria(candidate)\n",
      "  File \"C:\\Users\\Work\\anaconda3\\lib\\site-packages\\pip\\_vendor\\resolvelib\\resolvers.py\", line 230, in _get_updated_criteria\n",
      "    self._add_to_criteria(criteria, requirement, parent=candidate)\n",
      "  File \"C:\\Users\\Work\\anaconda3\\lib\\site-packages\\pip\\_vendor\\resolvelib\\resolvers.py\", line 148, in _add_to_criteria\n",
      "    matches = self._p.find_matches(\n",
      "  File \"C:\\Users\\Work\\anaconda3\\lib\\site-packages\\pip\\_internal\\resolution\\resolvelib\\provider.py\", line 231, in find_matches\n",
      "    return self._factory.find_candidates(\n",
      "  File \"C:\\Users\\Work\\anaconda3\\lib\\site-packages\\pip\\_internal\\resolution\\resolvelib\\factory.py\", line 424, in find_candidates\n",
      "    return self._iter_found_candidates(\n",
      "  File \"C:\\Users\\Work\\anaconda3\\lib\\site-packages\\pip\\_internal\\resolution\\resolvelib\\factory.py\", line 320, in _iter_found_candidates\n",
      "    _get_installed_candidate(),\n",
      "  File \"C:\\Users\\Work\\anaconda3\\lib\\site-packages\\pip\\_internal\\resolution\\resolvelib\\factory.py\", line 268, in _get_installed_candidate\n",
      "    candidate = self._make_candidate_from_dist(\n",
      "  File \"C:\\Users\\Work\\anaconda3\\lib\\site-packages\\pip\\_internal\\resolution\\resolvelib\\factory.py\", line 160, in _make_candidate_from_dist\n",
      "    base = AlreadyInstalledCandidate(dist, template, factory=self)\n",
      "  File \"C:\\Users\\Work\\anaconda3\\lib\\site-packages\\pip\\_internal\\resolution\\resolvelib\\candidates.py\", line 350, in __init__\n",
      "    factory.preparer.prepare_installed_requirement(self._ireq, skip_reason)\n",
      "  File \"C:\\Users\\Work\\anaconda3\\lib\\site-packages\\pip\\_internal\\operations\\prepare.py\", line 710, in prepare_installed_requirement\n",
      "    logger.info(\n",
      "  File \"C:\\Users\\Work\\anaconda3\\lib\\logging\\__init__.py\", line 1446, in info\n",
      "    self._log(INFO, msg, args, **kwargs)\n",
      "  File \"C:\\Users\\Work\\anaconda3\\lib\\logging\\__init__.py\", line 1589, in _log\n",
      "    self.handle(record)\n",
      "  File \"C:\\Users\\Work\\anaconda3\\lib\\logging\\__init__.py\", line 1599, in handle\n",
      "    self.callHandlers(record)\n",
      "  File \"C:\\Users\\Work\\anaconda3\\lib\\logging\\__init__.py\", line 1661, in callHandlers\n",
      "    hdlr.handle(record)\n",
      "  File \"C:\\Users\\Work\\anaconda3\\lib\\logging\\__init__.py\", line 952, in handle\n",
      "    self.emit(record)\n",
      "  File \"C:\\Users\\Work\\anaconda3\\lib\\site-packages\\pip\\_internal\\utils\\logging.py\", line 179, in emit\n",
      "    self.handleError(record)\n",
      "Message: 'Requirement %s: %s (%s)'\n",
      "Arguments: ('already satisfied', <InstallRequirement object: charset-normalizer<3,>=2 in c:\\users\\work\\anaconda3\\lib\\site-packages (from requests->Password-package==1.0.0) editable=False>, <Version('2.0.4')>)\n",
      "--- Logging error ---\n",
      "Traceback (most recent call last):\n",
      "  File \"C:\\Users\\Work\\anaconda3\\lib\\site-packages\\pip\\_internal\\resolution\\resolvelib\\factory.py\", line 158, in _make_candidate_from_dist\n",
      "    base = self._installed_candidate_cache[dist.canonical_name]\n",
      "KeyError: 'idna'\n",
      "\n",
      "During handling of the above exception, another exception occurred:\n",
      "\n",
      "Traceback (most recent call last):\n",
      "  File \"C:\\Users\\Work\\anaconda3\\lib\\site-packages\\pip\\_internal\\utils\\logging.py\", line 177, in emit\n",
      "    self.console.print(renderable, overflow=\"ignore\", crop=False, style=style)\n",
      "  File \"C:\\Users\\Work\\anaconda3\\lib\\site-packages\\pip\\_vendor\\rich\\console.py\", line 1719, in print\n",
      "    self._buffer.extend(new_segments)\n",
      "  File \"C:\\Users\\Work\\anaconda3\\lib\\site-packages\\pip\\_vendor\\rich\\console.py\", line 864, in __exit__\n",
      "    self._exit_buffer()\n",
      "  File \"C:\\Users\\Work\\anaconda3\\lib\\site-packages\\pip\\_vendor\\rich\\console.py\", line 822, in _exit_buffer\n",
      "    self._check_buffer()\n",
      "  File \"C:\\Users\\Work\\anaconda3\\lib\\site-packages\\pip\\_vendor\\rich\\console.py\", line 2027, in _check_buffer\n",
      "    legacy_windows_render(buffer, LegacyWindowsTerm(self.file))\n",
      "  File \"C:\\Users\\Work\\anaconda3\\lib\\site-packages\\pip\\_vendor\\rich\\_windows_renderer.py\", line 19, in legacy_windows_render\n",
      "    term.write_text(text)\n",
      "  File \"C:\\Users\\Work\\anaconda3\\lib\\site-packages\\pip\\_vendor\\rich\\_win32_console.py\", line 403, in write_text\n",
      "    self.write(text)\n",
      "  File \"C:\\Users\\Work\\anaconda3\\lib\\encodings\\cp1251.py\", line 19, in encode\n",
      "    return codecs.charmap_encode(input,self.errors,encoding_table)[0]\n",
      "UnicodeEncodeError: 'charmap' codec can't encode character '\\xf6' in position 77: character maps to <undefined>\n",
      "Call stack:\n",
      "  File \"C:\\Users\\Work\\anaconda3\\lib\\runpy.py\", line 197, in _run_module_as_main\n",
      "    return _run_code(code, main_globals, None,\n",
      "  File \"C:\\Users\\Work\\anaconda3\\lib\\runpy.py\", line 87, in _run_code\n",
      "    exec(code, run_globals)\n",
      "  File \"C:\\Users\\Work\\anaconda3\\Scripts\\pip.exe\\__main__.py\", line 7, in <module>\n",
      "    sys.exit(main())\n",
      "  File \"C:\\Users\\Work\\anaconda3\\lib\\site-packages\\pip\\_internal\\cli\\main.py\", line 79, in main\n",
      "    return command.main(cmd_args)\n",
      "  File \"C:\\Users\\Work\\anaconda3\\lib\\site-packages\\pip\\_internal\\cli\\base_command.py\", line 101, in main\n",
      "    return self._main(args)\n",
      "  File \"C:\\Users\\Work\\anaconda3\\lib\\site-packages\\pip\\_internal\\cli\\base_command.py\", line 223, in _main\n",
      "    return run(options, args)\n",
      "  File \"C:\\Users\\Work\\anaconda3\\lib\\site-packages\\pip\\_internal\\cli\\base_command.py\", line 169, in exc_logging_wrapper\n",
      "    status = run_func(*args)\n",
      "  File \"C:\\Users\\Work\\anaconda3\\lib\\site-packages\\pip\\_internal\\cli\\req_command.py\", line 248, in wrapper\n",
      "    return func(self, options, args)\n",
      "  File \"C:\\Users\\Work\\anaconda3\\lib\\site-packages\\pip\\_internal\\commands\\install.py\", line 377, in run\n",
      "    requirement_set = resolver.resolve(\n",
      "  File \"C:\\Users\\Work\\anaconda3\\lib\\site-packages\\pip\\_internal\\resolution\\resolvelib\\resolver.py\", line 92, in resolve\n",
      "    result = self._result = resolver.resolve(\n",
      "  File \"C:\\Users\\Work\\anaconda3\\lib\\site-packages\\pip\\_vendor\\resolvelib\\resolvers.py\", line 546, in resolve\n",
      "    state = resolution.resolve(requirements, max_rounds=max_rounds)\n",
      "  File \"C:\\Users\\Work\\anaconda3\\lib\\site-packages\\pip\\_vendor\\resolvelib\\resolvers.py\", line 427, in resolve\n",
      "    failure_causes = self._attempt_to_pin_criterion(name)\n",
      "  File \"C:\\Users\\Work\\anaconda3\\lib\\site-packages\\pip\\_vendor\\resolvelib\\resolvers.py\", line 239, in _attempt_to_pin_criterion\n",
      "    criteria = self._get_updated_criteria(candidate)\n",
      "  File \"C:\\Users\\Work\\anaconda3\\lib\\site-packages\\pip\\_vendor\\resolvelib\\resolvers.py\", line 230, in _get_updated_criteria\n",
      "    self._add_to_criteria(criteria, requirement, parent=candidate)\n",
      "  File \"C:\\Users\\Work\\anaconda3\\lib\\site-packages\\pip\\_vendor\\resolvelib\\resolvers.py\", line 148, in _add_to_criteria\n",
      "    matches = self._p.find_matches(\n",
      "  File \"C:\\Users\\Work\\anaconda3\\lib\\site-packages\\pip\\_internal\\resolution\\resolvelib\\provider.py\", line 231, in find_matches\n",
      "    return self._factory.find_candidates(\n",
      "  File \"C:\\Users\\Work\\anaconda3\\lib\\site-packages\\pip\\_internal\\resolution\\resolvelib\\factory.py\", line 424, in find_candidates\n",
      "    return self._iter_found_candidates(\n",
      "  File \"C:\\Users\\Work\\anaconda3\\lib\\site-packages\\pip\\_internal\\resolution\\resolvelib\\factory.py\", line 320, in _iter_found_candidates\n",
      "    _get_installed_candidate(),\n",
      "  File \"C:\\Users\\Work\\anaconda3\\lib\\site-packages\\pip\\_internal\\resolution\\resolvelib\\factory.py\", line 268, in _get_installed_candidate\n",
      "    candidate = self._make_candidate_from_dist(\n",
      "  File \"C:\\Users\\Work\\anaconda3\\lib\\site-packages\\pip\\_internal\\resolution\\resolvelib\\factory.py\", line 160, in _make_candidate_from_dist\n",
      "    base = AlreadyInstalledCandidate(dist, template, factory=self)\n",
      "  File \"C:\\Users\\Work\\anaconda3\\lib\\site-packages\\pip\\_internal\\resolution\\resolvelib\\candidates.py\", line 350, in __init__\n",
      "    factory.preparer.prepare_installed_requirement(self._ireq, skip_reason)\n",
      "  File \"C:\\Users\\Work\\anaconda3\\lib\\site-packages\\pip\\_internal\\operations\\prepare.py\", line 710, in prepare_installed_requirement\n",
      "    logger.info(\n",
      "  File \"C:\\Users\\Work\\anaconda3\\lib\\logging\\__init__.py\", line 1446, in info\n",
      "    self._log(INFO, msg, args, **kwargs)\n",
      "  File \"C:\\Users\\Work\\anaconda3\\lib\\logging\\__init__.py\", line 1589, in _log\n",
      "    self.handle(record)\n",
      "  File \"C:\\Users\\Work\\anaconda3\\lib\\logging\\__init__.py\", line 1599, in handle\n",
      "    self.callHandlers(record)\n",
      "  File \"C:\\Users\\Work\\anaconda3\\lib\\logging\\__init__.py\", line 1661, in callHandlers\n",
      "    hdlr.handle(record)\n",
      "  File \"C:\\Users\\Work\\anaconda3\\lib\\logging\\__init__.py\", line 952, in handle\n",
      "    self.emit(record)\n",
      "  File \"C:\\Users\\Work\\anaconda3\\lib\\site-packages\\pip\\_internal\\utils\\logging.py\", line 179, in emit\n",
      "    self.handleError(record)\n",
      "Message: 'Requirement %s: %s (%s)'\n",
      "Arguments: ('already satisfied', <InstallRequirement object: idna<4,>=2.5 in c:\\users\\work\\anaconda3\\lib\\site-packages (from requests->Password-package==1.0.0) editable=False>, <Version('3.3')>)\n",
      "--- Logging error ---\n",
      "Traceback (most recent call last):\n",
      "  File \"C:\\Users\\Work\\anaconda3\\lib\\site-packages\\pip\\_internal\\resolution\\resolvelib\\factory.py\", line 158, in _make_candidate_from_dist\n",
      "    base = self._installed_candidate_cache[dist.canonical_name]\n",
      "KeyError: 'urllib3'\n",
      "\n",
      "During handling of the above exception, another exception occurred:\n",
      "\n",
      "Traceback (most recent call last):\n",
      "  File \"C:\\Users\\Work\\anaconda3\\lib\\site-packages\\pip\\_internal\\utils\\logging.py\", line 177, in emit\n",
      "    self.console.print(renderable, overflow=\"ignore\", crop=False, style=style)\n",
      "  File \"C:\\Users\\Work\\anaconda3\\lib\\site-packages\\pip\\_vendor\\rich\\console.py\", line 1719, in print\n",
      "    self._buffer.extend(new_segments)\n",
      "  File \"C:\\Users\\Work\\anaconda3\\lib\\site-packages\\pip\\_vendor\\rich\\console.py\", line 864, in __exit__\n",
      "    self._exit_buffer()\n",
      "  File \"C:\\Users\\Work\\anaconda3\\lib\\site-packages\\pip\\_vendor\\rich\\console.py\", line 822, in _exit_buffer\n",
      "    self._check_buffer()\n",
      "  File \"C:\\Users\\Work\\anaconda3\\lib\\site-packages\\pip\\_vendor\\rich\\console.py\", line 2027, in _check_buffer\n",
      "    legacy_windows_render(buffer, LegacyWindowsTerm(self.file))\n",
      "  File \"C:\\Users\\Work\\anaconda3\\lib\\site-packages\\pip\\_vendor\\rich\\_windows_renderer.py\", line 19, in legacy_windows_render\n",
      "    term.write_text(text)\n",
      "  File \"C:\\Users\\Work\\anaconda3\\lib\\site-packages\\pip\\_vendor\\rich\\_win32_console.py\", line 403, in write_text\n",
      "    self.write(text)\n",
      "  File \"C:\\Users\\Work\\anaconda3\\lib\\encodings\\cp1251.py\", line 19, in encode\n",
      "    return codecs.charmap_encode(input,self.errors,encoding_table)[0]\n",
      "UnicodeEncodeError: 'charmap' codec can't encode character '\\xf6' in position 77: character maps to <undefined>\n",
      "Call stack:\n",
      "  File \"C:\\Users\\Work\\anaconda3\\lib\\runpy.py\", line 197, in _run_module_as_main\n",
      "    return _run_code(code, main_globals, None,\n",
      "  File \"C:\\Users\\Work\\anaconda3\\lib\\runpy.py\", line 87, in _run_code\n",
      "    exec(code, run_globals)\n",
      "  File \"C:\\Users\\Work\\anaconda3\\Scripts\\pip.exe\\__main__.py\", line 7, in <module>\n",
      "    sys.exit(main())\n",
      "  File \"C:\\Users\\Work\\anaconda3\\lib\\site-packages\\pip\\_internal\\cli\\main.py\", line 79, in main\n",
      "    return command.main(cmd_args)\n",
      "  File \"C:\\Users\\Work\\anaconda3\\lib\\site-packages\\pip\\_internal\\cli\\base_command.py\", line 101, in main\n",
      "    return self._main(args)\n",
      "  File \"C:\\Users\\Work\\anaconda3\\lib\\site-packages\\pip\\_internal\\cli\\base_command.py\", line 223, in _main\n",
      "    return run(options, args)\n",
      "  File \"C:\\Users\\Work\\anaconda3\\lib\\site-packages\\pip\\_internal\\cli\\base_command.py\", line 169, in exc_logging_wrapper\n",
      "    status = run_func(*args)\n",
      "  File \"C:\\Users\\Work\\anaconda3\\lib\\site-packages\\pip\\_internal\\cli\\req_command.py\", line 248, in wrapper\n",
      "    return func(self, options, args)\n",
      "  File \"C:\\Users\\Work\\anaconda3\\lib\\site-packages\\pip\\_internal\\commands\\install.py\", line 377, in run\n",
      "    requirement_set = resolver.resolve(\n",
      "  File \"C:\\Users\\Work\\anaconda3\\lib\\site-packages\\pip\\_internal\\resolution\\resolvelib\\resolver.py\", line 92, in resolve\n",
      "    result = self._result = resolver.resolve(\n",
      "  File \"C:\\Users\\Work\\anaconda3\\lib\\site-packages\\pip\\_vendor\\resolvelib\\resolvers.py\", line 546, in resolve\n",
      "    state = resolution.resolve(requirements, max_rounds=max_rounds)\n",
      "  File \"C:\\Users\\Work\\anaconda3\\lib\\site-packages\\pip\\_vendor\\resolvelib\\resolvers.py\", line 427, in resolve\n",
      "    failure_causes = self._attempt_to_pin_criterion(name)\n",
      "  File \"C:\\Users\\Work\\anaconda3\\lib\\site-packages\\pip\\_vendor\\resolvelib\\resolvers.py\", line 239, in _attempt_to_pin_criterion\n",
      "    criteria = self._get_updated_criteria(candidate)\n",
      "  File \"C:\\Users\\Work\\anaconda3\\lib\\site-packages\\pip\\_vendor\\resolvelib\\resolvers.py\", line 230, in _get_updated_criteria\n",
      "    self._add_to_criteria(criteria, requirement, parent=candidate)\n",
      "  File \"C:\\Users\\Work\\anaconda3\\lib\\site-packages\\pip\\_vendor\\resolvelib\\resolvers.py\", line 148, in _add_to_criteria\n",
      "    matches = self._p.find_matches(\n",
      "  File \"C:\\Users\\Work\\anaconda3\\lib\\site-packages\\pip\\_internal\\resolution\\resolvelib\\provider.py\", line 231, in find_matches\n",
      "    return self._factory.find_candidates(\n",
      "  File \"C:\\Users\\Work\\anaconda3\\lib\\site-packages\\pip\\_internal\\resolution\\resolvelib\\factory.py\", line 424, in find_candidates\n",
      "    return self._iter_found_candidates(\n",
      "  File \"C:\\Users\\Work\\anaconda3\\lib\\site-packages\\pip\\_internal\\resolution\\resolvelib\\factory.py\", line 320, in _iter_found_candidates\n",
      "    _get_installed_candidate(),\n",
      "  File \"C:\\Users\\Work\\anaconda3\\lib\\site-packages\\pip\\_internal\\resolution\\resolvelib\\factory.py\", line 268, in _get_installed_candidate\n",
      "    candidate = self._make_candidate_from_dist(\n",
      "  File \"C:\\Users\\Work\\anaconda3\\lib\\site-packages\\pip\\_internal\\resolution\\resolvelib\\factory.py\", line 160, in _make_candidate_from_dist\n",
      "    base = AlreadyInstalledCandidate(dist, template, factory=self)\n",
      "  File \"C:\\Users\\Work\\anaconda3\\lib\\site-packages\\pip\\_internal\\resolution\\resolvelib\\candidates.py\", line 350, in __init__\n",
      "    factory.preparer.prepare_installed_requirement(self._ireq, skip_reason)\n",
      "  File \"C:\\Users\\Work\\anaconda3\\lib\\site-packages\\pip\\_internal\\operations\\prepare.py\", line 710, in prepare_installed_requirement\n",
      "    logger.info(\n",
      "  File \"C:\\Users\\Work\\anaconda3\\lib\\logging\\__init__.py\", line 1446, in info\n",
      "    self._log(INFO, msg, args, **kwargs)\n",
      "  File \"C:\\Users\\Work\\anaconda3\\lib\\logging\\__init__.py\", line 1589, in _log\n",
      "    self.handle(record)\n",
      "  File \"C:\\Users\\Work\\anaconda3\\lib\\logging\\__init__.py\", line 1599, in handle\n",
      "    self.callHandlers(record)\n",
      "  File \"C:\\Users\\Work\\anaconda3\\lib\\logging\\__init__.py\", line 1661, in callHandlers\n",
      "    hdlr.handle(record)\n",
      "  File \"C:\\Users\\Work\\anaconda3\\lib\\logging\\__init__.py\", line 952, in handle\n",
      "    self.emit(record)\n",
      "  File \"C:\\Users\\Work\\anaconda3\\lib\\site-packages\\pip\\_internal\\utils\\logging.py\", line 179, in emit\n",
      "    self.handleError(record)\n",
      "Message: 'Requirement %s: %s (%s)'\n",
      "Arguments: ('already satisfied', <InstallRequirement object: urllib3<1.27,>=1.21.1 in c:\\users\\work\\anaconda3\\lib\\site-packages (from requests->Password-package==1.0.0) editable=False>, <Version('1.26.11')>)\n",
      "--- Logging error ---\n",
      "Traceback (most recent call last):\n",
      "  File \"C:\\Users\\Work\\anaconda3\\lib\\site-packages\\pip\\_internal\\resolution\\resolvelib\\factory.py\", line 158, in _make_candidate_from_dist\n",
      "    base = self._installed_candidate_cache[dist.canonical_name]\n",
      "KeyError: 'certifi'\n",
      "\n",
      "During handling of the above exception, another exception occurred:\n",
      "\n",
      "Traceback (most recent call last):\n",
      "  File \"C:\\Users\\Work\\anaconda3\\lib\\site-packages\\pip\\_internal\\utils\\logging.py\", line 177, in emit\n",
      "    self.console.print(renderable, overflow=\"ignore\", crop=False, style=style)\n",
      "  File \"C:\\Users\\Work\\anaconda3\\lib\\site-packages\\pip\\_vendor\\rich\\console.py\", line 1719, in print\n",
      "    self._buffer.extend(new_segments)\n",
      "  File \"C:\\Users\\Work\\anaconda3\\lib\\site-packages\\pip\\_vendor\\rich\\console.py\", line 864, in __exit__\n",
      "    self._exit_buffer()\n",
      "  File \"C:\\Users\\Work\\anaconda3\\lib\\site-packages\\pip\\_vendor\\rich\\console.py\", line 822, in _exit_buffer\n",
      "    self._check_buffer()\n",
      "  File \"C:\\Users\\Work\\anaconda3\\lib\\site-packages\\pip\\_vendor\\rich\\console.py\", line 2027, in _check_buffer\n",
      "    legacy_windows_render(buffer, LegacyWindowsTerm(self.file))\n",
      "  File \"C:\\Users\\Work\\anaconda3\\lib\\site-packages\\pip\\_vendor\\rich\\_windows_renderer.py\", line 19, in legacy_windows_render\n",
      "    term.write_text(text)\n",
      "  File \"C:\\Users\\Work\\anaconda3\\lib\\site-packages\\pip\\_vendor\\rich\\_win32_console.py\", line 403, in write_text\n",
      "    self.write(text)\n",
      "  File \"C:\\Users\\Work\\anaconda3\\lib\\encodings\\cp1251.py\", line 19, in encode\n",
      "    return codecs.charmap_encode(input,self.errors,encoding_table)[0]\n",
      "UnicodeEncodeError: 'charmap' codec can't encode character '\\xf6' in position 77: character maps to <undefined>\n",
      "Call stack:\n",
      "  File \"C:\\Users\\Work\\anaconda3\\lib\\runpy.py\", line 197, in _run_module_as_main\n",
      "    return _run_code(code, main_globals, None,\n",
      "  File \"C:\\Users\\Work\\anaconda3\\lib\\runpy.py\", line 87, in _run_code\n",
      "    exec(code, run_globals)\n",
      "  File \"C:\\Users\\Work\\anaconda3\\Scripts\\pip.exe\\__main__.py\", line 7, in <module>\n",
      "    sys.exit(main())\n",
      "  File \"C:\\Users\\Work\\anaconda3\\lib\\site-packages\\pip\\_internal\\cli\\main.py\", line 79, in main\n",
      "    return command.main(cmd_args)\n",
      "  File \"C:\\Users\\Work\\anaconda3\\lib\\site-packages\\pip\\_internal\\cli\\base_command.py\", line 101, in main\n",
      "    return self._main(args)\n",
      "  File \"C:\\Users\\Work\\anaconda3\\lib\\site-packages\\pip\\_internal\\cli\\base_command.py\", line 223, in _main\n",
      "    return run(options, args)\n",
      "  File \"C:\\Users\\Work\\anaconda3\\lib\\site-packages\\pip\\_internal\\cli\\base_command.py\", line 169, in exc_logging_wrapper\n",
      "    status = run_func(*args)\n",
      "  File \"C:\\Users\\Work\\anaconda3\\lib\\site-packages\\pip\\_internal\\cli\\req_command.py\", line 248, in wrapper\n",
      "    return func(self, options, args)\n",
      "  File \"C:\\Users\\Work\\anaconda3\\lib\\site-packages\\pip\\_internal\\commands\\install.py\", line 377, in run\n",
      "    requirement_set = resolver.resolve(\n",
      "  File \"C:\\Users\\Work\\anaconda3\\lib\\site-packages\\pip\\_internal\\resolution\\resolvelib\\resolver.py\", line 92, in resolve\n",
      "    result = self._result = resolver.resolve(\n",
      "  File \"C:\\Users\\Work\\anaconda3\\lib\\site-packages\\pip\\_vendor\\resolvelib\\resolvers.py\", line 546, in resolve\n",
      "    state = resolution.resolve(requirements, max_rounds=max_rounds)\n",
      "  File \"C:\\Users\\Work\\anaconda3\\lib\\site-packages\\pip\\_vendor\\resolvelib\\resolvers.py\", line 427, in resolve\n",
      "    failure_causes = self._attempt_to_pin_criterion(name)\n",
      "  File \"C:\\Users\\Work\\anaconda3\\lib\\site-packages\\pip\\_vendor\\resolvelib\\resolvers.py\", line 239, in _attempt_to_pin_criterion\n",
      "    criteria = self._get_updated_criteria(candidate)\n",
      "  File \"C:\\Users\\Work\\anaconda3\\lib\\site-packages\\pip\\_vendor\\resolvelib\\resolvers.py\", line 230, in _get_updated_criteria\n",
      "    self._add_to_criteria(criteria, requirement, parent=candidate)\n",
      "  File \"C:\\Users\\Work\\anaconda3\\lib\\site-packages\\pip\\_vendor\\resolvelib\\resolvers.py\", line 148, in _add_to_criteria\n",
      "    matches = self._p.find_matches(\n",
      "  File \"C:\\Users\\Work\\anaconda3\\lib\\site-packages\\pip\\_internal\\resolution\\resolvelib\\provider.py\", line 231, in find_matches\n",
      "    return self._factory.find_candidates(\n",
      "  File \"C:\\Users\\Work\\anaconda3\\lib\\site-packages\\pip\\_internal\\resolution\\resolvelib\\factory.py\", line 424, in find_candidates\n",
      "    return self._iter_found_candidates(\n",
      "  File \"C:\\Users\\Work\\anaconda3\\lib\\site-packages\\pip\\_internal\\resolution\\resolvelib\\factory.py\", line 320, in _iter_found_candidates\n",
      "    _get_installed_candidate(),\n",
      "  File \"C:\\Users\\Work\\anaconda3\\lib\\site-packages\\pip\\_internal\\resolution\\resolvelib\\factory.py\", line 268, in _get_installed_candidate\n",
      "    candidate = self._make_candidate_from_dist(\n",
      "  File \"C:\\Users\\Work\\anaconda3\\lib\\site-packages\\pip\\_internal\\resolution\\resolvelib\\factory.py\", line 160, in _make_candidate_from_dist\n",
      "    base = AlreadyInstalledCandidate(dist, template, factory=self)\n",
      "  File \"C:\\Users\\Work\\anaconda3\\lib\\site-packages\\pip\\_internal\\resolution\\resolvelib\\candidates.py\", line 350, in __init__\n",
      "    factory.preparer.prepare_installed_requirement(self._ireq, skip_reason)\n",
      "  File \"C:\\Users\\Work\\anaconda3\\lib\\site-packages\\pip\\_internal\\operations\\prepare.py\", line 710, in prepare_installed_requirement\n",
      "    logger.info(\n",
      "  File \"C:\\Users\\Work\\anaconda3\\lib\\logging\\__init__.py\", line 1446, in info\n",
      "    self._log(INFO, msg, args, **kwargs)\n",
      "  File \"C:\\Users\\Work\\anaconda3\\lib\\logging\\__init__.py\", line 1589, in _log\n",
      "    self.handle(record)\n",
      "  File \"C:\\Users\\Work\\anaconda3\\lib\\logging\\__init__.py\", line 1599, in handle\n",
      "    self.callHandlers(record)\n",
      "  File \"C:\\Users\\Work\\anaconda3\\lib\\logging\\__init__.py\", line 1661, in callHandlers\n",
      "    hdlr.handle(record)\n",
      "  File \"C:\\Users\\Work\\anaconda3\\lib\\logging\\__init__.py\", line 952, in handle\n",
      "    self.emit(record)\n",
      "  File \"C:\\Users\\Work\\anaconda3\\lib\\site-packages\\pip\\_internal\\utils\\logging.py\", line 179, in emit\n",
      "    self.handleError(record)\n",
      "Message: 'Requirement %s: %s (%s)'\n",
      "Arguments: ('already satisfied', <InstallRequirement object: certifi>=2017.4.17 in c:\\users\\work\\anaconda3\\lib\\site-packages (from requests->Password-package==1.0.0) editable=False>, <Version('2022.9.14')>)\n",
      "--- Logging error ---\n",
      "Traceback (most recent call last):\n",
      "  File \"C:\\Users\\Work\\anaconda3\\lib\\site-packages\\pip\\_internal\\utils\\logging.py\", line 177, in emit\n",
      "    self.console.print(renderable, overflow=\"ignore\", crop=False, style=style)\n",
      "  File \"C:\\Users\\Work\\anaconda3\\lib\\site-packages\\pip\\_vendor\\rich\\console.py\", line 1719, in print\n",
      "    self._buffer.extend(new_segments)\n",
      "  File \"C:\\Users\\Work\\anaconda3\\lib\\site-packages\\pip\\_vendor\\rich\\console.py\", line 864, in __exit__\n",
      "    self._exit_buffer()\n",
      "  File \"C:\\Users\\Work\\anaconda3\\lib\\site-packages\\pip\\_vendor\\rich\\console.py\", line 822, in _exit_buffer\n",
      "    self._check_buffer()\n",
      "  File \"C:\\Users\\Work\\anaconda3\\lib\\site-packages\\pip\\_vendor\\rich\\console.py\", line 2027, in _check_buffer\n",
      "    legacy_windows_render(buffer, LegacyWindowsTerm(self.file))\n",
      "  File \"C:\\Users\\Work\\anaconda3\\lib\\site-packages\\pip\\_vendor\\rich\\_windows_renderer.py\", line 19, in legacy_windows_render\n",
      "    term.write_text(text)\n",
      "  File \"C:\\Users\\Work\\anaconda3\\lib\\site-packages\\pip\\_vendor\\rich\\_win32_console.py\", line 403, in write_text\n",
      "    self.write(text)\n",
      "  File \"C:\\Users\\Work\\anaconda3\\lib\\encodings\\cp1251.py\", line 19, in encode\n",
      "    return codecs.charmap_encode(input,self.errors,encoding_table)[0]\n",
      "UnicodeEncodeError: 'charmap' codec can't encode character '\\xf6' in position 77: character maps to <undefined>\n",
      "Call stack:\n",
      "  File \"C:\\Users\\Work\\anaconda3\\lib\\runpy.py\", line 197, in _run_module_as_main\n",
      "    return _run_code(code, main_globals, None,\n",
      "  File \"C:\\Users\\Work\\anaconda3\\lib\\runpy.py\", line 87, in _run_code\n",
      "    exec(code, run_globals)\n",
      "  File \"C:\\Users\\Work\\anaconda3\\Scripts\\pip.exe\\__main__.py\", line 7, in <module>\n",
      "    sys.exit(main())\n",
      "  File \"C:\\Users\\Work\\anaconda3\\lib\\site-packages\\pip\\_internal\\cli\\main.py\", line 79, in main\n",
      "    return command.main(cmd_args)\n",
      "  File \"C:\\Users\\Work\\anaconda3\\lib\\site-packages\\pip\\_internal\\cli\\base_command.py\", line 101, in main\n",
      "    return self._main(args)\n",
      "  File \"C:\\Users\\Work\\anaconda3\\lib\\site-packages\\pip\\_internal\\cli\\base_command.py\", line 223, in _main\n",
      "    return run(options, args)\n",
      "  File \"C:\\Users\\Work\\anaconda3\\lib\\site-packages\\pip\\_internal\\cli\\base_command.py\", line 169, in exc_logging_wrapper\n",
      "    status = run_func(*args)\n",
      "  File \"C:\\Users\\Work\\anaconda3\\lib\\site-packages\\pip\\_internal\\cli\\req_command.py\", line 248, in wrapper\n",
      "    return func(self, options, args)\n",
      "  File \"C:\\Users\\Work\\anaconda3\\lib\\site-packages\\pip\\_internal\\commands\\install.py\", line 417, in run\n",
      "    _, build_failures = build(\n",
      "  File \"C:\\Users\\Work\\anaconda3\\lib\\site-packages\\pip\\_internal\\wheel_builder.py\", line 310, in build\n",
      "    logger.info(\n",
      "  File \"C:\\Users\\Work\\anaconda3\\lib\\logging\\__init__.py\", line 1446, in info\n",
      "    self._log(INFO, msg, args, **kwargs)\n",
      "  File \"C:\\Users\\Work\\anaconda3\\lib\\logging\\__init__.py\", line 1589, in _log\n",
      "    self.handle(record)\n",
      "  File \"C:\\Users\\Work\\anaconda3\\lib\\logging\\__init__.py\", line 1599, in handle\n",
      "    self.callHandlers(record)\n",
      "  File \"C:\\Users\\Work\\anaconda3\\lib\\logging\\__init__.py\", line 1661, in callHandlers\n",
      "    hdlr.handle(record)\n",
      "  File \"C:\\Users\\Work\\anaconda3\\lib\\logging\\__init__.py\", line 952, in handle\n",
      "    self.emit(record)\n",
      "  File \"C:\\Users\\Work\\anaconda3\\lib\\site-packages\\pip\\_internal\\utils\\logging.py\", line 179, in emit\n",
      "    self.handleError(record)\n",
      "Message: 'Building wheels for collected packages: %s'\n",
      "Arguments: ('Password-package',)\n",
      "--- Logging error ---\n",
      "Traceback (most recent call last):\n",
      "  File \"C:\\Users\\Work\\anaconda3\\lib\\site-packages\\pip\\_internal\\utils\\logging.py\", line 177, in emit\n",
      "    self.console.print(renderable, overflow=\"ignore\", crop=False, style=style)\n",
      "  File \"C:\\Users\\Work\\anaconda3\\lib\\site-packages\\pip\\_vendor\\rich\\console.py\", line 1719, in print\n",
      "    self._buffer.extend(new_segments)\n",
      "  File \"C:\\Users\\Work\\anaconda3\\lib\\site-packages\\pip\\_vendor\\rich\\console.py\", line 864, in __exit__\n",
      "    self._exit_buffer()\n",
      "  File \"C:\\Users\\Work\\anaconda3\\lib\\site-packages\\pip\\_vendor\\rich\\console.py\", line 822, in _exit_buffer\n",
      "    self._check_buffer()\n",
      "  File \"C:\\Users\\Work\\anaconda3\\lib\\site-packages\\pip\\_vendor\\rich\\console.py\", line 2027, in _check_buffer\n",
      "    legacy_windows_render(buffer, LegacyWindowsTerm(self.file))\n",
      "  File \"C:\\Users\\Work\\anaconda3\\lib\\site-packages\\pip\\_vendor\\rich\\_windows_renderer.py\", line 19, in legacy_windows_render\n",
      "    term.write_text(text)\n",
      "  File \"C:\\Users\\Work\\anaconda3\\lib\\site-packages\\pip\\_vendor\\rich\\_win32_console.py\", line 403, in write_text\n",
      "    self.write(text)\n",
      "  File \"C:\\Users\\Work\\anaconda3\\lib\\encodings\\cp1251.py\", line 19, in encode\n",
      "    return codecs.charmap_encode(input,self.errors,encoding_table)[0]\n",
      "UnicodeEncodeError: 'charmap' codec can't encode character '\\xf6' in position 77: character maps to <undefined>\n",
      "Call stack:\n",
      "  File \"C:\\Users\\Work\\anaconda3\\lib\\runpy.py\", line 197, in _run_module_as_main\n",
      "    return _run_code(code, main_globals, None,\n",
      "  File \"C:\\Users\\Work\\anaconda3\\lib\\runpy.py\", line 87, in _run_code\n",
      "    exec(code, run_globals)\n",
      "  File \"C:\\Users\\Work\\anaconda3\\Scripts\\pip.exe\\__main__.py\", line 7, in <module>\n",
      "    sys.exit(main())\n",
      "  File \"C:\\Users\\Work\\anaconda3\\lib\\site-packages\\pip\\_internal\\cli\\main.py\", line 79, in main\n",
      "    return command.main(cmd_args)\n",
      "  File \"C:\\Users\\Work\\anaconda3\\lib\\site-packages\\pip\\_internal\\cli\\base_command.py\", line 101, in main\n",
      "    return self._main(args)\n",
      "  File \"C:\\Users\\Work\\anaconda3\\lib\\site-packages\\pip\\_internal\\cli\\base_command.py\", line 223, in _main\n",
      "    return run(options, args)\n",
      "  File \"C:\\Users\\Work\\anaconda3\\lib\\site-packages\\pip\\_internal\\cli\\base_command.py\", line 169, in exc_logging_wrapper\n",
      "    status = run_func(*args)\n",
      "  File \"C:\\Users\\Work\\anaconda3\\lib\\site-packages\\pip\\_internal\\cli\\req_command.py\", line 248, in wrapper\n",
      "    return func(self, options, args)\n",
      "  File \"C:\\Users\\Work\\anaconda3\\lib\\site-packages\\pip\\_internal\\commands\\install.py\", line 417, in run\n",
      "    _, build_failures = build(\n",
      "  File \"C:\\Users\\Work\\anaconda3\\lib\\site-packages\\pip\\_internal\\wheel_builder.py\", line 320, in build\n",
      "    wheel_file = _build_one(\n",
      "  File \"C:\\Users\\Work\\anaconda3\\lib\\site-packages\\pip\\_internal\\wheel_builder.py\", line 194, in _build_one\n",
      "    wheel_path = _build_one_inside_env(\n",
      "  File \"C:\\Users\\Work\\anaconda3\\lib\\site-packages\\pip\\_internal\\wheel_builder.py\", line 234, in _build_one_inside_env\n",
      "    wheel_path = build_wheel_pep517(\n",
      "  File \"C:\\Users\\Work\\anaconda3\\lib\\site-packages\\pip\\_internal\\operations\\build\\wheel.py\", line 30, in build_wheel_pep517\n",
      "    wheel_name = backend.build_wheel(\n",
      "  File \"C:\\Users\\Work\\anaconda3\\lib\\site-packages\\pip\\_internal\\utils\\misc.py\", line 665, in build_wheel\n",
      "    return super().build_wheel(\n",
      "  File \"C:\\Users\\Work\\anaconda3\\lib\\site-packages\\pip\\_vendor\\pyproject_hooks\\_impl.py\", line 209, in build_wheel\n",
      "    return self._call_hook('build_wheel', {\n",
      "  File \"C:\\Users\\Work\\anaconda3\\lib\\site-packages\\pip\\_vendor\\pyproject_hooks\\_impl.py\", line 311, in _call_hook\n",
      "    self._subprocess_runner(\n",
      "  File \"C:\\Users\\Work\\anaconda3\\lib\\site-packages\\pip\\_internal\\utils\\subprocess.py\", line 251, in runner\n",
      "    with open_spinner(message) as spinner:\n",
      "  File \"C:\\Users\\Work\\anaconda3\\lib\\contextlib.py\", line 119, in __enter__\n",
      "    return next(self.gen)\n",
      "  File \"C:\\Users\\Work\\anaconda3\\lib\\site-packages\\pip\\_internal\\cli\\spinners.py\", line 125, in open_spinner\n",
      "    spinner = NonInteractiveSpinner(message)\n",
      "  File \"C:\\Users\\Work\\anaconda3\\lib\\site-packages\\pip\\_internal\\cli\\spinners.py\", line 80, in __init__\n",
      "    self._update(\"started\")\n",
      "  File \"C:\\Users\\Work\\anaconda3\\lib\\site-packages\\pip\\_internal\\cli\\spinners.py\", line 85, in _update\n",
      "    logger.info(\"%s: %s\", self._message, status)\n",
      "  File \"C:\\Users\\Work\\anaconda3\\lib\\logging\\__init__.py\", line 1446, in info\n",
      "    self._log(INFO, msg, args, **kwargs)\n",
      "  File \"C:\\Users\\Work\\anaconda3\\lib\\logging\\__init__.py\", line 1589, in _log\n",
      "    self.handle(record)\n",
      "  File \"C:\\Users\\Work\\anaconda3\\lib\\logging\\__init__.py\", line 1599, in handle\n",
      "    self.callHandlers(record)\n",
      "  File \"C:\\Users\\Work\\anaconda3\\lib\\logging\\__init__.py\", line 1661, in callHandlers\n",
      "    hdlr.handle(record)\n",
      "  File \"C:\\Users\\Work\\anaconda3\\lib\\logging\\__init__.py\", line 952, in handle\n",
      "    self.emit(record)\n",
      "  File \"C:\\Users\\Work\\anaconda3\\lib\\site-packages\\pip\\_internal\\utils\\logging.py\", line 179, in emit\n",
      "    self.handleError(record)\n",
      "Message: '%s: %s'\n",
      "Arguments: ('Building wheel for Password-package (pyproject.toml)', 'started')\n",
      "--- Logging error ---\n",
      "Traceback (most recent call last):\n",
      "  File \"C:\\Users\\Work\\anaconda3\\lib\\site-packages\\pip\\_internal\\utils\\logging.py\", line 177, in emit\n",
      "    self.console.print(renderable, overflow=\"ignore\", crop=False, style=style)\n",
      "  File \"C:\\Users\\Work\\anaconda3\\lib\\site-packages\\pip\\_vendor\\rich\\console.py\", line 1719, in print\n",
      "    self._buffer.extend(new_segments)\n",
      "  File \"C:\\Users\\Work\\anaconda3\\lib\\site-packages\\pip\\_vendor\\rich\\console.py\", line 864, in __exit__\n",
      "    self._exit_buffer()\n",
      "  File \"C:\\Users\\Work\\anaconda3\\lib\\site-packages\\pip\\_vendor\\rich\\console.py\", line 822, in _exit_buffer\n",
      "    self._check_buffer()\n",
      "  File \"C:\\Users\\Work\\anaconda3\\lib\\site-packages\\pip\\_vendor\\rich\\console.py\", line 2027, in _check_buffer\n",
      "    legacy_windows_render(buffer, LegacyWindowsTerm(self.file))\n",
      "  File \"C:\\Users\\Work\\anaconda3\\lib\\site-packages\\pip\\_vendor\\rich\\_windows_renderer.py\", line 19, in legacy_windows_render\n",
      "    term.write_text(text)\n",
      "  File \"C:\\Users\\Work\\anaconda3\\lib\\site-packages\\pip\\_vendor\\rich\\_win32_console.py\", line 403, in write_text\n",
      "    self.write(text)\n",
      "  File \"C:\\Users\\Work\\anaconda3\\lib\\encodings\\cp1251.py\", line 19, in encode\n",
      "    return codecs.charmap_encode(input,self.errors,encoding_table)[0]\n",
      "UnicodeEncodeError: 'charmap' codec can't encode character '\\xf6' in position 77: character maps to <undefined>\n",
      "Call stack:\n",
      "  File \"C:\\Users\\Work\\anaconda3\\lib\\runpy.py\", line 197, in _run_module_as_main\n",
      "    return _run_code(code, main_globals, None,\n",
      "  File \"C:\\Users\\Work\\anaconda3\\lib\\runpy.py\", line 87, in _run_code\n",
      "    exec(code, run_globals)\n",
      "  File \"C:\\Users\\Work\\anaconda3\\Scripts\\pip.exe\\__main__.py\", line 7, in <module>\n",
      "    sys.exit(main())\n",
      "  File \"C:\\Users\\Work\\anaconda3\\lib\\site-packages\\pip\\_internal\\cli\\main.py\", line 79, in main\n",
      "    return command.main(cmd_args)\n",
      "  File \"C:\\Users\\Work\\anaconda3\\lib\\site-packages\\pip\\_internal\\cli\\base_command.py\", line 101, in main\n",
      "    return self._main(args)\n",
      "  File \"C:\\Users\\Work\\anaconda3\\lib\\site-packages\\pip\\_internal\\cli\\base_command.py\", line 223, in _main\n",
      "    return run(options, args)\n",
      "  File \"C:\\Users\\Work\\anaconda3\\lib\\site-packages\\pip\\_internal\\cli\\base_command.py\", line 169, in exc_logging_wrapper\n",
      "    status = run_func(*args)\n",
      "  File \"C:\\Users\\Work\\anaconda3\\lib\\site-packages\\pip\\_internal\\cli\\req_command.py\", line 248, in wrapper\n",
      "    return func(self, options, args)\n",
      "  File \"C:\\Users\\Work\\anaconda3\\lib\\site-packages\\pip\\_internal\\commands\\install.py\", line 417, in run\n",
      "    _, build_failures = build(\n",
      "  File \"C:\\Users\\Work\\anaconda3\\lib\\site-packages\\pip\\_internal\\wheel_builder.py\", line 320, in build\n",
      "    wheel_file = _build_one(\n",
      "  File \"C:\\Users\\Work\\anaconda3\\lib\\site-packages\\pip\\_internal\\wheel_builder.py\", line 194, in _build_one\n",
      "    wheel_path = _build_one_inside_env(\n",
      "  File \"C:\\Users\\Work\\anaconda3\\lib\\site-packages\\pip\\_internal\\wheel_builder.py\", line 234, in _build_one_inside_env\n",
      "    wheel_path = build_wheel_pep517(\n",
      "  File \"C:\\Users\\Work\\anaconda3\\lib\\site-packages\\pip\\_internal\\operations\\build\\wheel.py\", line 30, in build_wheel_pep517\n",
      "    wheel_name = backend.build_wheel(\n",
      "  File \"C:\\Users\\Work\\anaconda3\\lib\\site-packages\\pip\\_internal\\utils\\misc.py\", line 665, in build_wheel\n",
      "    return super().build_wheel(\n",
      "  File \"C:\\Users\\Work\\anaconda3\\lib\\site-packages\\pip\\_vendor\\pyproject_hooks\\_impl.py\", line 209, in build_wheel\n",
      "    return self._call_hook('build_wheel', {\n",
      "  File \"C:\\Users\\Work\\anaconda3\\lib\\site-packages\\pip\\_vendor\\pyproject_hooks\\_impl.py\", line 311, in _call_hook\n",
      "    self._subprocess_runner(\n",
      "  File \"C:\\Users\\Work\\anaconda3\\lib\\site-packages\\pip\\_internal\\utils\\subprocess.py\", line 252, in runner\n",
      "    call_subprocess(\n",
      "  File \"C:\\Users\\Work\\anaconda3\\lib\\site-packages\\pip\\_internal\\utils\\subprocess.py\", line 203, in call_subprocess\n",
      "    spinner.finish(\"done\")\n",
      "  File \"C:\\Users\\Work\\anaconda3\\lib\\site-packages\\pip\\_internal\\cli\\spinners.py\", line 97, in finish\n",
      "    self._update(f\"finished with status '{final_status}'\")\n",
      "  File \"C:\\Users\\Work\\anaconda3\\lib\\site-packages\\pip\\_internal\\cli\\spinners.py\", line 85, in _update\n",
      "    logger.info(\"%s: %s\", self._message, status)\n",
      "  File \"C:\\Users\\Work\\anaconda3\\lib\\logging\\__init__.py\", line 1446, in info\n",
      "    self._log(INFO, msg, args, **kwargs)\n",
      "  File \"C:\\Users\\Work\\anaconda3\\lib\\logging\\__init__.py\", line 1589, in _log\n",
      "    self.handle(record)\n",
      "  File \"C:\\Users\\Work\\anaconda3\\lib\\logging\\__init__.py\", line 1599, in handle\n",
      "    self.callHandlers(record)\n",
      "  File \"C:\\Users\\Work\\anaconda3\\lib\\logging\\__init__.py\", line 1661, in callHandlers\n",
      "    hdlr.handle(record)\n",
      "  File \"C:\\Users\\Work\\anaconda3\\lib\\logging\\__init__.py\", line 952, in handle\n",
      "    self.emit(record)\n",
      "  File \"C:\\Users\\Work\\anaconda3\\lib\\site-packages\\pip\\_internal\\utils\\logging.py\", line 179, in emit\n",
      "    self.handleError(record)\n",
      "Message: '%s: %s'\n",
      "Arguments: ('Building wheel for Password-package (pyproject.toml)', \"finished with status 'done'\")\n",
      "--- Logging error ---\n",
      "Traceback (most recent call last):\n",
      "  File \"C:\\Users\\Work\\anaconda3\\lib\\site-packages\\pip\\_internal\\utils\\logging.py\", line 177, in emit\n",
      "    self.console.print(renderable, overflow=\"ignore\", crop=False, style=style)\n",
      "  File \"C:\\Users\\Work\\anaconda3\\lib\\site-packages\\pip\\_vendor\\rich\\console.py\", line 1719, in print\n",
      "    self._buffer.extend(new_segments)\n",
      "  File \"C:\\Users\\Work\\anaconda3\\lib\\site-packages\\pip\\_vendor\\rich\\console.py\", line 864, in __exit__\n",
      "    self._exit_buffer()\n",
      "  File \"C:\\Users\\Work\\anaconda3\\lib\\site-packages\\pip\\_vendor\\rich\\console.py\", line 822, in _exit_buffer\n",
      "    self._check_buffer()\n",
      "  File \"C:\\Users\\Work\\anaconda3\\lib\\site-packages\\pip\\_vendor\\rich\\console.py\", line 2027, in _check_buffer\n",
      "    legacy_windows_render(buffer, LegacyWindowsTerm(self.file))\n",
      "  File \"C:\\Users\\Work\\anaconda3\\lib\\site-packages\\pip\\_vendor\\rich\\_windows_renderer.py\", line 19, in legacy_windows_render\n",
      "    term.write_text(text)\n",
      "  File \"C:\\Users\\Work\\anaconda3\\lib\\site-packages\\pip\\_vendor\\rich\\_win32_console.py\", line 403, in write_text\n",
      "    self.write(text)\n",
      "  File \"C:\\Users\\Work\\anaconda3\\lib\\encodings\\cp1251.py\", line 19, in encode\n",
      "    return codecs.charmap_encode(input,self.errors,encoding_table)[0]\n",
      "UnicodeEncodeError: 'charmap' codec can't encode character '\\xf6' in position 77: character maps to <undefined>\n",
      "Call stack:\n",
      "  File \"C:\\Users\\Work\\anaconda3\\lib\\runpy.py\", line 197, in _run_module_as_main\n",
      "    return _run_code(code, main_globals, None,\n",
      "  File \"C:\\Users\\Work\\anaconda3\\lib\\runpy.py\", line 87, in _run_code\n",
      "    exec(code, run_globals)\n",
      "  File \"C:\\Users\\Work\\anaconda3\\Scripts\\pip.exe\\__main__.py\", line 7, in <module>\n",
      "    sys.exit(main())\n",
      "  File \"C:\\Users\\Work\\anaconda3\\lib\\site-packages\\pip\\_internal\\cli\\main.py\", line 79, in main\n",
      "    return command.main(cmd_args)\n",
      "  File \"C:\\Users\\Work\\anaconda3\\lib\\site-packages\\pip\\_internal\\cli\\base_command.py\", line 101, in main\n",
      "    return self._main(args)\n",
      "  File \"C:\\Users\\Work\\anaconda3\\lib\\site-packages\\pip\\_internal\\cli\\base_command.py\", line 223, in _main\n",
      "    return run(options, args)\n",
      "  File \"C:\\Users\\Work\\anaconda3\\lib\\site-packages\\pip\\_internal\\cli\\base_command.py\", line 169, in exc_logging_wrapper\n",
      "    status = run_func(*args)\n",
      "  File \"C:\\Users\\Work\\anaconda3\\lib\\site-packages\\pip\\_internal\\cli\\req_command.py\", line 248, in wrapper\n",
      "    return func(self, options, args)\n",
      "  File \"C:\\Users\\Work\\anaconda3\\lib\\site-packages\\pip\\_internal\\commands\\install.py\", line 417, in run\n",
      "    _, build_failures = build(\n",
      "  File \"C:\\Users\\Work\\anaconda3\\lib\\site-packages\\pip\\_internal\\wheel_builder.py\", line 320, in build\n",
      "    wheel_file = _build_one(\n",
      "  File \"C:\\Users\\Work\\anaconda3\\lib\\site-packages\\pip\\_internal\\wheel_builder.py\", line 194, in _build_one\n",
      "    wheel_path = _build_one_inside_env(\n",
      "  File \"C:\\Users\\Work\\anaconda3\\lib\\site-packages\\pip\\_internal\\wheel_builder.py\", line 256, in _build_one_inside_env\n",
      "    logger.info(\n",
      "  File \"C:\\Users\\Work\\anaconda3\\lib\\logging\\__init__.py\", line 1446, in info\n",
      "    self._log(INFO, msg, args, **kwargs)\n",
      "  File \"C:\\Users\\Work\\anaconda3\\lib\\logging\\__init__.py\", line 1589, in _log\n",
      "    self.handle(record)\n",
      "  File \"C:\\Users\\Work\\anaconda3\\lib\\logging\\__init__.py\", line 1599, in handle\n",
      "    self.callHandlers(record)\n",
      "  File \"C:\\Users\\Work\\anaconda3\\lib\\logging\\__init__.py\", line 1661, in callHandlers\n",
      "    hdlr.handle(record)\n",
      "  File \"C:\\Users\\Work\\anaconda3\\lib\\logging\\__init__.py\", line 952, in handle\n",
      "    self.emit(record)\n",
      "  File \"C:\\Users\\Work\\anaconda3\\lib\\site-packages\\pip\\_internal\\utils\\logging.py\", line 179, in emit\n",
      "    self.handleError(record)\n",
      "Message: 'Created wheel for %s: filename=%s size=%d sha256=%s'\n",
      "Arguments: ('Password-package', 'Password_package-1.0.0-py3-none-any.whl', 4060, '3586af844f98a38f3e135bb4d8728f648af5fd42458cb2309234b39f3b3d9d7d')\n",
      "--- Logging error ---\n",
      "Traceback (most recent call last):\n",
      "  File \"C:\\Users\\Work\\anaconda3\\lib\\site-packages\\pip\\_internal\\utils\\logging.py\", line 177, in emit\n",
      "    self.console.print(renderable, overflow=\"ignore\", crop=False, style=style)\n",
      "  File \"C:\\Users\\Work\\anaconda3\\lib\\site-packages\\pip\\_vendor\\rich\\console.py\", line 1719, in print\n",
      "    self._buffer.extend(new_segments)\n",
      "  File \"C:\\Users\\Work\\anaconda3\\lib\\site-packages\\pip\\_vendor\\rich\\console.py\", line 864, in __exit__\n",
      "    self._exit_buffer()\n",
      "  File \"C:\\Users\\Work\\anaconda3\\lib\\site-packages\\pip\\_vendor\\rich\\console.py\", line 822, in _exit_buffer\n",
      "    self._check_buffer()\n",
      "  File \"C:\\Users\\Work\\anaconda3\\lib\\site-packages\\pip\\_vendor\\rich\\console.py\", line 2027, in _check_buffer\n",
      "    legacy_windows_render(buffer, LegacyWindowsTerm(self.file))\n",
      "  File \"C:\\Users\\Work\\anaconda3\\lib\\site-packages\\pip\\_vendor\\rich\\_windows_renderer.py\", line 19, in legacy_windows_render\n",
      "    term.write_text(text)\n",
      "  File \"C:\\Users\\Work\\anaconda3\\lib\\site-packages\\pip\\_vendor\\rich\\_win32_console.py\", line 403, in write_text\n",
      "    self.write(text)\n",
      "  File \"C:\\Users\\Work\\anaconda3\\lib\\encodings\\cp1251.py\", line 19, in encode\n",
      "    return codecs.charmap_encode(input,self.errors,encoding_table)[0]\n",
      "UnicodeEncodeError: 'charmap' codec can't encode character '\\xf6' in position 77: character maps to <undefined>\n",
      "Call stack:\n",
      "  File \"C:\\Users\\Work\\anaconda3\\lib\\runpy.py\", line 197, in _run_module_as_main\n",
      "    return _run_code(code, main_globals, None,\n",
      "  File \"C:\\Users\\Work\\anaconda3\\lib\\runpy.py\", line 87, in _run_code\n",
      "    exec(code, run_globals)\n",
      "  File \"C:\\Users\\Work\\anaconda3\\Scripts\\pip.exe\\__main__.py\", line 7, in <module>\n",
      "    sys.exit(main())\n",
      "  File \"C:\\Users\\Work\\anaconda3\\lib\\site-packages\\pip\\_internal\\cli\\main.py\", line 79, in main\n",
      "    return command.main(cmd_args)\n",
      "  File \"C:\\Users\\Work\\anaconda3\\lib\\site-packages\\pip\\_internal\\cli\\base_command.py\", line 101, in main\n",
      "    return self._main(args)\n",
      "  File \"C:\\Users\\Work\\anaconda3\\lib\\site-packages\\pip\\_internal\\cli\\base_command.py\", line 223, in _main\n",
      "    return run(options, args)\n",
      "  File \"C:\\Users\\Work\\anaconda3\\lib\\site-packages\\pip\\_internal\\cli\\base_command.py\", line 169, in exc_logging_wrapper\n",
      "    status = run_func(*args)\n",
      "  File \"C:\\Users\\Work\\anaconda3\\lib\\site-packages\\pip\\_internal\\cli\\req_command.py\", line 248, in wrapper\n",
      "    return func(self, options, args)\n",
      "  File \"C:\\Users\\Work\\anaconda3\\lib\\site-packages\\pip\\_internal\\commands\\install.py\", line 417, in run\n",
      "    _, build_failures = build(\n",
      "  File \"C:\\Users\\Work\\anaconda3\\lib\\site-packages\\pip\\_internal\\wheel_builder.py\", line 320, in build\n",
      "    wheel_file = _build_one(\n",
      "  File \"C:\\Users\\Work\\anaconda3\\lib\\site-packages\\pip\\_internal\\wheel_builder.py\", line 194, in _build_one\n",
      "    wheel_path = _build_one_inside_env(\n",
      "  File \"C:\\Users\\Work\\anaconda3\\lib\\site-packages\\pip\\_internal\\wheel_builder.py\", line 263, in _build_one_inside_env\n",
      "    logger.info(\"Stored in directory: %s\", output_dir)\n",
      "  File \"C:\\Users\\Work\\anaconda3\\lib\\logging\\__init__.py\", line 1446, in info\n",
      "    self._log(INFO, msg, args, **kwargs)\n",
      "  File \"C:\\Users\\Work\\anaconda3\\lib\\logging\\__init__.py\", line 1589, in _log\n",
      "    self.handle(record)\n",
      "  File \"C:\\Users\\Work\\anaconda3\\lib\\logging\\__init__.py\", line 1599, in handle\n",
      "    self.callHandlers(record)\n",
      "  File \"C:\\Users\\Work\\anaconda3\\lib\\logging\\__init__.py\", line 1661, in callHandlers\n",
      "    hdlr.handle(record)\n",
      "  File \"C:\\Users\\Work\\anaconda3\\lib\\logging\\__init__.py\", line 952, in handle\n",
      "    self.emit(record)\n",
      "  File \"C:\\Users\\Work\\anaconda3\\lib\\site-packages\\pip\\_internal\\utils\\logging.py\", line 179, in emit\n",
      "    self.handleError(record)\n",
      "Message: 'Stored in directory: %s'\n",
      "Arguments: ('C:\\\\Users\\\\Work\\\\AppData\\\\Local\\\\Temp\\\\pip-ephem-wheel-cache-6f_60h2y\\\\wheels\\\\b2\\\\b5\\\\a9\\\\af2ba12a72663f72d3a9ee57cf1a02d6eaa291eb4c2feaddd4',)\n",
      "--- Logging error ---\n",
      "Traceback (most recent call last):\n",
      "  File \"C:\\Users\\Work\\anaconda3\\lib\\site-packages\\pip\\_internal\\utils\\logging.py\", line 177, in emit\n",
      "    self.console.print(renderable, overflow=\"ignore\", crop=False, style=style)\n",
      "  File \"C:\\Users\\Work\\anaconda3\\lib\\site-packages\\pip\\_vendor\\rich\\console.py\", line 1719, in print\n",
      "    self._buffer.extend(new_segments)\n",
      "  File \"C:\\Users\\Work\\anaconda3\\lib\\site-packages\\pip\\_vendor\\rich\\console.py\", line 864, in __exit__\n",
      "    self._exit_buffer()\n",
      "  File \"C:\\Users\\Work\\anaconda3\\lib\\site-packages\\pip\\_vendor\\rich\\console.py\", line 822, in _exit_buffer\n",
      "    self._check_buffer()\n",
      "  File \"C:\\Users\\Work\\anaconda3\\lib\\site-packages\\pip\\_vendor\\rich\\console.py\", line 2027, in _check_buffer\n",
      "    legacy_windows_render(buffer, LegacyWindowsTerm(self.file))\n",
      "  File \"C:\\Users\\Work\\anaconda3\\lib\\site-packages\\pip\\_vendor\\rich\\_windows_renderer.py\", line 19, in legacy_windows_render\n",
      "    term.write_text(text)\n",
      "  File \"C:\\Users\\Work\\anaconda3\\lib\\site-packages\\pip\\_vendor\\rich\\_win32_console.py\", line 403, in write_text\n",
      "    self.write(text)\n",
      "  File \"C:\\Users\\Work\\anaconda3\\lib\\encodings\\cp1251.py\", line 19, in encode\n",
      "    return codecs.charmap_encode(input,self.errors,encoding_table)[0]\n",
      "UnicodeEncodeError: 'charmap' codec can't encode character '\\xf6' in position 77: character maps to <undefined>\n",
      "Call stack:\n",
      "  File \"C:\\Users\\Work\\anaconda3\\lib\\runpy.py\", line 197, in _run_module_as_main\n",
      "    return _run_code(code, main_globals, None,\n",
      "  File \"C:\\Users\\Work\\anaconda3\\lib\\runpy.py\", line 87, in _run_code\n",
      "    exec(code, run_globals)\n",
      "  File \"C:\\Users\\Work\\anaconda3\\Scripts\\pip.exe\\__main__.py\", line 7, in <module>\n",
      "    sys.exit(main())\n",
      "  File \"C:\\Users\\Work\\anaconda3\\lib\\site-packages\\pip\\_internal\\cli\\main.py\", line 79, in main\n",
      "    return command.main(cmd_args)\n",
      "  File \"C:\\Users\\Work\\anaconda3\\lib\\site-packages\\pip\\_internal\\cli\\base_command.py\", line 101, in main\n",
      "    return self._main(args)\n",
      "  File \"C:\\Users\\Work\\anaconda3\\lib\\site-packages\\pip\\_internal\\cli\\base_command.py\", line 223, in _main\n",
      "    return run(options, args)\n",
      "  File \"C:\\Users\\Work\\anaconda3\\lib\\site-packages\\pip\\_internal\\cli\\base_command.py\", line 169, in exc_logging_wrapper\n",
      "    status = run_func(*args)\n",
      "  File \"C:\\Users\\Work\\anaconda3\\lib\\site-packages\\pip\\_internal\\cli\\req_command.py\", line 248, in wrapper\n",
      "    return func(self, options, args)\n",
      "  File \"C:\\Users\\Work\\anaconda3\\lib\\site-packages\\pip\\_internal\\commands\\install.py\", line 417, in run\n",
      "    _, build_failures = build(\n",
      "  File \"C:\\Users\\Work\\anaconda3\\lib\\site-packages\\pip\\_internal\\wheel_builder.py\", line 345, in build\n",
      "    logger.info(\n",
      "  File \"C:\\Users\\Work\\anaconda3\\lib\\logging\\__init__.py\", line 1446, in info\n",
      "    self._log(INFO, msg, args, **kwargs)\n",
      "  File \"C:\\Users\\Work\\anaconda3\\lib\\logging\\__init__.py\", line 1589, in _log\n",
      "    self.handle(record)\n",
      "  File \"C:\\Users\\Work\\anaconda3\\lib\\logging\\__init__.py\", line 1599, in handle\n",
      "    self.callHandlers(record)\n",
      "  File \"C:\\Users\\Work\\anaconda3\\lib\\logging\\__init__.py\", line 1661, in callHandlers\n",
      "    hdlr.handle(record)\n",
      "  File \"C:\\Users\\Work\\anaconda3\\lib\\logging\\__init__.py\", line 952, in handle\n",
      "    self.emit(record)\n",
      "  File \"C:\\Users\\Work\\anaconda3\\lib\\site-packages\\pip\\_internal\\utils\\logging.py\", line 179, in emit\n",
      "    self.handleError(record)\n",
      "Message: 'Successfully built %s'\n",
      "Arguments: ('Password-package',)\n",
      "--- Logging error ---\n",
      "Traceback (most recent call last):\n",
      "  File \"C:\\Users\\Work\\anaconda3\\lib\\site-packages\\pip\\_internal\\utils\\logging.py\", line 177, in emit\n",
      "    self.console.print(renderable, overflow=\"ignore\", crop=False, style=style)\n",
      "  File \"C:\\Users\\Work\\anaconda3\\lib\\site-packages\\pip\\_vendor\\rich\\console.py\", line 1719, in print\n",
      "    self._buffer.extend(new_segments)\n",
      "  File \"C:\\Users\\Work\\anaconda3\\lib\\site-packages\\pip\\_vendor\\rich\\console.py\", line 864, in __exit__\n",
      "    self._exit_buffer()\n",
      "  File \"C:\\Users\\Work\\anaconda3\\lib\\site-packages\\pip\\_vendor\\rich\\console.py\", line 822, in _exit_buffer\n",
      "    self._check_buffer()\n",
      "  File \"C:\\Users\\Work\\anaconda3\\lib\\site-packages\\pip\\_vendor\\rich\\console.py\", line 2027, in _check_buffer\n",
      "    legacy_windows_render(buffer, LegacyWindowsTerm(self.file))\n",
      "  File \"C:\\Users\\Work\\anaconda3\\lib\\site-packages\\pip\\_vendor\\rich\\_windows_renderer.py\", line 19, in legacy_windows_render\n",
      "    term.write_text(text)\n",
      "  File \"C:\\Users\\Work\\anaconda3\\lib\\site-packages\\pip\\_vendor\\rich\\_win32_console.py\", line 403, in write_text\n",
      "    self.write(text)\n",
      "  File \"C:\\Users\\Work\\anaconda3\\lib\\encodings\\cp1251.py\", line 19, in encode\n",
      "    return codecs.charmap_encode(input,self.errors,encoding_table)[0]\n",
      "UnicodeEncodeError: 'charmap' codec can't encode character '\\xf6' in position 77: character maps to <undefined>\n",
      "Call stack:\n",
      "  File \"C:\\Users\\Work\\anaconda3\\lib\\runpy.py\", line 197, in _run_module_as_main\n",
      "    return _run_code(code, main_globals, None,\n",
      "  File \"C:\\Users\\Work\\anaconda3\\lib\\runpy.py\", line 87, in _run_code\n",
      "    exec(code, run_globals)\n",
      "  File \"C:\\Users\\Work\\anaconda3\\Scripts\\pip.exe\\__main__.py\", line 7, in <module>\n",
      "    sys.exit(main())\n",
      "  File \"C:\\Users\\Work\\anaconda3\\lib\\site-packages\\pip\\_internal\\cli\\main.py\", line 79, in main\n",
      "    return command.main(cmd_args)\n",
      "  File \"C:\\Users\\Work\\anaconda3\\lib\\site-packages\\pip\\_internal\\cli\\base_command.py\", line 101, in main\n",
      "    return self._main(args)\n",
      "  File \"C:\\Users\\Work\\anaconda3\\lib\\site-packages\\pip\\_internal\\cli\\base_command.py\", line 223, in _main\n",
      "    return run(options, args)\n",
      "  File \"C:\\Users\\Work\\anaconda3\\lib\\site-packages\\pip\\_internal\\cli\\base_command.py\", line 169, in exc_logging_wrapper\n",
      "    status = run_func(*args)\n",
      "  File \"C:\\Users\\Work\\anaconda3\\lib\\site-packages\\pip\\_internal\\cli\\req_command.py\", line 248, in wrapper\n",
      "    return func(self, options, args)\n",
      "  File \"C:\\Users\\Work\\anaconda3\\lib\\site-packages\\pip\\_internal\\commands\\install.py\", line 449, in run\n",
      "    installed = install_given_reqs(\n",
      "  File \"C:\\Users\\Work\\anaconda3\\lib\\site-packages\\pip\\_internal\\req\\__init__.py\", line 55, in install_given_reqs\n",
      "    logger.info(\n",
      "  File \"C:\\Users\\Work\\anaconda3\\lib\\logging\\__init__.py\", line 1446, in info\n",
      "    self._log(INFO, msg, args, **kwargs)\n",
      "  File \"C:\\Users\\Work\\anaconda3\\lib\\logging\\__init__.py\", line 1589, in _log\n",
      "    self.handle(record)\n",
      "  File \"C:\\Users\\Work\\anaconda3\\lib\\logging\\__init__.py\", line 1599, in handle\n",
      "    self.callHandlers(record)\n",
      "  File \"C:\\Users\\Work\\anaconda3\\lib\\logging\\__init__.py\", line 1661, in callHandlers\n",
      "    hdlr.handle(record)\n",
      "  File \"C:\\Users\\Work\\anaconda3\\lib\\logging\\__init__.py\", line 952, in handle\n",
      "    self.emit(record)\n",
      "  File \"C:\\Users\\Work\\anaconda3\\lib\\site-packages\\pip\\_internal\\utils\\logging.py\", line 179, in emit\n",
      "    self.handleError(record)\n",
      "Message: 'Installing collected packages: %s'\n",
      "Arguments: ('Password-package',)\n",
      "--- Logging error ---\n",
      "Traceback (most recent call last):\n",
      "  File \"C:\\Users\\Work\\anaconda3\\lib\\site-packages\\pip\\_internal\\utils\\logging.py\", line 177, in emit\n",
      "    self.console.print(renderable, overflow=\"ignore\", crop=False, style=style)\n",
      "  File \"C:\\Users\\Work\\anaconda3\\lib\\site-packages\\pip\\_vendor\\rich\\console.py\", line 1719, in print\n",
      "    self._buffer.extend(new_segments)\n",
      "  File \"C:\\Users\\Work\\anaconda3\\lib\\site-packages\\pip\\_vendor\\rich\\console.py\", line 864, in __exit__\n",
      "    self._exit_buffer()\n",
      "  File \"C:\\Users\\Work\\anaconda3\\lib\\site-packages\\pip\\_vendor\\rich\\console.py\", line 822, in _exit_buffer\n",
      "    self._check_buffer()\n",
      "  File \"C:\\Users\\Work\\anaconda3\\lib\\site-packages\\pip\\_vendor\\rich\\console.py\", line 2027, in _check_buffer\n",
      "    legacy_windows_render(buffer, LegacyWindowsTerm(self.file))\n",
      "  File \"C:\\Users\\Work\\anaconda3\\lib\\site-packages\\pip\\_vendor\\rich\\_windows_renderer.py\", line 19, in legacy_windows_render\n",
      "    term.write_text(text)\n",
      "  File \"C:\\Users\\Work\\anaconda3\\lib\\site-packages\\pip\\_vendor\\rich\\_win32_console.py\", line 403, in write_text\n",
      "    self.write(text)\n",
      "  File \"C:\\Users\\Work\\anaconda3\\lib\\encodings\\cp1251.py\", line 19, in encode\n",
      "    return codecs.charmap_encode(input,self.errors,encoding_table)[0]\n",
      "UnicodeEncodeError: 'charmap' codec can't encode character '\\xf6' in position 77: character maps to <undefined>\n",
      "Call stack:\n",
      "  File \"C:\\Users\\Work\\anaconda3\\lib\\runpy.py\", line 197, in _run_module_as_main\n",
      "    return _run_code(code, main_globals, None,\n",
      "  File \"C:\\Users\\Work\\anaconda3\\lib\\runpy.py\", line 87, in _run_code\n",
      "    exec(code, run_globals)\n",
      "  File \"C:\\Users\\Work\\anaconda3\\Scripts\\pip.exe\\__main__.py\", line 7, in <module>\n",
      "    sys.exit(main())\n",
      "  File \"C:\\Users\\Work\\anaconda3\\lib\\site-packages\\pip\\_internal\\cli\\main.py\", line 79, in main\n",
      "    return command.main(cmd_args)\n",
      "  File \"C:\\Users\\Work\\anaconda3\\lib\\site-packages\\pip\\_internal\\cli\\base_command.py\", line 101, in main\n",
      "    return self._main(args)\n",
      "  File \"C:\\Users\\Work\\anaconda3\\lib\\site-packages\\pip\\_internal\\cli\\base_command.py\", line 223, in _main\n",
      "    return run(options, args)\n",
      "  File \"C:\\Users\\Work\\anaconda3\\lib\\site-packages\\pip\\_internal\\cli\\base_command.py\", line 169, in exc_logging_wrapper\n",
      "    status = run_func(*args)\n",
      "  File \"C:\\Users\\Work\\anaconda3\\lib\\site-packages\\pip\\_internal\\cli\\req_command.py\", line 248, in wrapper\n",
      "    return func(self, options, args)\n",
      "  File \"C:\\Users\\Work\\anaconda3\\lib\\site-packages\\pip\\_internal\\commands\\install.py\", line 449, in run\n",
      "    installed = install_given_reqs(\n",
      "  File \"C:\\Users\\Work\\anaconda3\\lib\\site-packages\\pip\\_internal\\req\\__init__.py\", line 65, in install_given_reqs\n",
      "    logger.info(\"Attempting uninstall: %s\", req_name)\n",
      "  File \"C:\\Users\\Work\\anaconda3\\lib\\logging\\__init__.py\", line 1446, in info\n",
      "    self._log(INFO, msg, args, **kwargs)\n",
      "  File \"C:\\Users\\Work\\anaconda3\\lib\\logging\\__init__.py\", line 1589, in _log\n",
      "    self.handle(record)\n",
      "  File \"C:\\Users\\Work\\anaconda3\\lib\\logging\\__init__.py\", line 1599, in handle\n",
      "    self.callHandlers(record)\n",
      "  File \"C:\\Users\\Work\\anaconda3\\lib\\logging\\__init__.py\", line 1661, in callHandlers\n",
      "    hdlr.handle(record)\n",
      "  File \"C:\\Users\\Work\\anaconda3\\lib\\logging\\__init__.py\", line 952, in handle\n",
      "    self.emit(record)\n",
      "  File \"C:\\Users\\Work\\anaconda3\\lib\\site-packages\\pip\\_internal\\utils\\logging.py\", line 179, in emit\n",
      "    self.handleError(record)\n",
      "Message: 'Attempting uninstall: %s'\n",
      "Arguments: ('Password-package',)\n",
      "--- Logging error ---\n",
      "Traceback (most recent call last):\n",
      "  File \"C:\\Users\\Work\\anaconda3\\lib\\site-packages\\pip\\_internal\\utils\\logging.py\", line 177, in emit\n",
      "    self.console.print(renderable, overflow=\"ignore\", crop=False, style=style)\n",
      "  File \"C:\\Users\\Work\\anaconda3\\lib\\site-packages\\pip\\_vendor\\rich\\console.py\", line 1719, in print\n",
      "    self._buffer.extend(new_segments)\n",
      "  File \"C:\\Users\\Work\\anaconda3\\lib\\site-packages\\pip\\_vendor\\rich\\console.py\", line 864, in __exit__\n",
      "    self._exit_buffer()\n",
      "  File \"C:\\Users\\Work\\anaconda3\\lib\\site-packages\\pip\\_vendor\\rich\\console.py\", line 822, in _exit_buffer\n",
      "    self._check_buffer()\n",
      "  File \"C:\\Users\\Work\\anaconda3\\lib\\site-packages\\pip\\_vendor\\rich\\console.py\", line 2027, in _check_buffer\n",
      "    legacy_windows_render(buffer, LegacyWindowsTerm(self.file))\n",
      "  File \"C:\\Users\\Work\\anaconda3\\lib\\site-packages\\pip\\_vendor\\rich\\_windows_renderer.py\", line 19, in legacy_windows_render\n",
      "    term.write_text(text)\n",
      "  File \"C:\\Users\\Work\\anaconda3\\lib\\site-packages\\pip\\_vendor\\rich\\_win32_console.py\", line 403, in write_text\n",
      "    self.write(text)\n",
      "  File \"C:\\Users\\Work\\anaconda3\\lib\\encodings\\cp1251.py\", line 19, in encode\n",
      "    return codecs.charmap_encode(input,self.errors,encoding_table)[0]\n",
      "UnicodeEncodeError: 'charmap' codec can't encode character '\\xf6' in position 77: character maps to <undefined>\n",
      "Call stack:\n",
      "  File \"C:\\Users\\Work\\anaconda3\\lib\\runpy.py\", line 197, in _run_module_as_main\n",
      "    return _run_code(code, main_globals, None,\n",
      "  File \"C:\\Users\\Work\\anaconda3\\lib\\runpy.py\", line 87, in _run_code\n",
      "    exec(code, run_globals)\n",
      "  File \"C:\\Users\\Work\\anaconda3\\Scripts\\pip.exe\\__main__.py\", line 7, in <module>\n",
      "    sys.exit(main())\n",
      "  File \"C:\\Users\\Work\\anaconda3\\lib\\site-packages\\pip\\_internal\\cli\\main.py\", line 79, in main\n",
      "    return command.main(cmd_args)\n",
      "  File \"C:\\Users\\Work\\anaconda3\\lib\\site-packages\\pip\\_internal\\cli\\base_command.py\", line 101, in main\n",
      "    return self._main(args)\n",
      "  File \"C:\\Users\\Work\\anaconda3\\lib\\site-packages\\pip\\_internal\\cli\\base_command.py\", line 223, in _main\n",
      "    return run(options, args)\n",
      "  File \"C:\\Users\\Work\\anaconda3\\lib\\site-packages\\pip\\_internal\\cli\\base_command.py\", line 169, in exc_logging_wrapper\n",
      "    status = run_func(*args)\n",
      "  File \"C:\\Users\\Work\\anaconda3\\lib\\site-packages\\pip\\_internal\\cli\\req_command.py\", line 248, in wrapper\n",
      "    return func(self, options, args)\n",
      "  File \"C:\\Users\\Work\\anaconda3\\lib\\site-packages\\pip\\_internal\\commands\\install.py\", line 449, in run\n",
      "    installed = install_given_reqs(\n",
      "  File \"C:\\Users\\Work\\anaconda3\\lib\\site-packages\\pip\\_internal\\req\\__init__.py\", line 67, in install_given_reqs\n",
      "    uninstalled_pathset = requirement.uninstall(auto_confirm=True)\n",
      "  File \"C:\\Users\\Work\\anaconda3\\lib\\site-packages\\pip\\_internal\\req\\req_install.py\", line 677, in uninstall\n",
      "    logger.info(\"Found existing installation: %s\", dist)\n",
      "  File \"C:\\Users\\Work\\anaconda3\\lib\\logging\\__init__.py\", line 1446, in info\n",
      "    self._log(INFO, msg, args, **kwargs)\n",
      "  File \"C:\\Users\\Work\\anaconda3\\lib\\logging\\__init__.py\", line 1589, in _log\n",
      "    self.handle(record)\n",
      "  File \"C:\\Users\\Work\\anaconda3\\lib\\logging\\__init__.py\", line 1599, in handle\n",
      "    self.callHandlers(record)\n",
      "  File \"C:\\Users\\Work\\anaconda3\\lib\\logging\\__init__.py\", line 1661, in callHandlers\n",
      "    hdlr.handle(record)\n",
      "  File \"C:\\Users\\Work\\anaconda3\\lib\\logging\\__init__.py\", line 952, in handle\n",
      "    self.emit(record)\n",
      "  File \"C:\\Users\\Work\\anaconda3\\lib\\site-packages\\pip\\_internal\\utils\\logging.py\", line 179, in emit\n",
      "    self.handleError(record)\n",
      "Message: 'Found existing installation: %s'\n",
      "Arguments: (Password-package 1.0.0 (c:\\users\\work\\anaconda3\\lib\\site-packages),)\n",
      "--- Logging error ---\n",
      "Traceback (most recent call last):\n",
      "  File \"C:\\Users\\Work\\anaconda3\\lib\\site-packages\\pip\\_internal\\utils\\logging.py\", line 177, in emit\n",
      "    self.console.print(renderable, overflow=\"ignore\", crop=False, style=style)\n",
      "  File \"C:\\Users\\Work\\anaconda3\\lib\\site-packages\\pip\\_vendor\\rich\\console.py\", line 1719, in print\n",
      "    self._buffer.extend(new_segments)\n",
      "  File \"C:\\Users\\Work\\anaconda3\\lib\\site-packages\\pip\\_vendor\\rich\\console.py\", line 864, in __exit__\n",
      "    self._exit_buffer()\n",
      "  File \"C:\\Users\\Work\\anaconda3\\lib\\site-packages\\pip\\_vendor\\rich\\console.py\", line 822, in _exit_buffer\n",
      "    self._check_buffer()\n",
      "  File \"C:\\Users\\Work\\anaconda3\\lib\\site-packages\\pip\\_vendor\\rich\\console.py\", line 2027, in _check_buffer\n",
      "    legacy_windows_render(buffer, LegacyWindowsTerm(self.file))\n",
      "  File \"C:\\Users\\Work\\anaconda3\\lib\\site-packages\\pip\\_vendor\\rich\\_windows_renderer.py\", line 19, in legacy_windows_render\n",
      "    term.write_text(text)\n",
      "  File \"C:\\Users\\Work\\anaconda3\\lib\\site-packages\\pip\\_vendor\\rich\\_win32_console.py\", line 403, in write_text\n",
      "    self.write(text)\n",
      "  File \"C:\\Users\\Work\\anaconda3\\lib\\encodings\\cp1251.py\", line 19, in encode\n",
      "    return codecs.charmap_encode(input,self.errors,encoding_table)[0]\n",
      "UnicodeEncodeError: 'charmap' codec can't encode character '\\xf6' in position 77: character maps to <undefined>\n",
      "Call stack:\n",
      "  File \"C:\\Users\\Work\\anaconda3\\lib\\runpy.py\", line 197, in _run_module_as_main\n",
      "    return _run_code(code, main_globals, None,\n",
      "  File \"C:\\Users\\Work\\anaconda3\\lib\\runpy.py\", line 87, in _run_code\n",
      "    exec(code, run_globals)\n",
      "  File \"C:\\Users\\Work\\anaconda3\\Scripts\\pip.exe\\__main__.py\", line 7, in <module>\n",
      "    sys.exit(main())\n",
      "  File \"C:\\Users\\Work\\anaconda3\\lib\\site-packages\\pip\\_internal\\cli\\main.py\", line 79, in main\n",
      "    return command.main(cmd_args)\n",
      "  File \"C:\\Users\\Work\\anaconda3\\lib\\site-packages\\pip\\_internal\\cli\\base_command.py\", line 101, in main\n",
      "    return self._main(args)\n",
      "  File \"C:\\Users\\Work\\anaconda3\\lib\\site-packages\\pip\\_internal\\cli\\base_command.py\", line 223, in _main\n",
      "    return run(options, args)\n",
      "  File \"C:\\Users\\Work\\anaconda3\\lib\\site-packages\\pip\\_internal\\cli\\base_command.py\", line 169, in exc_logging_wrapper\n",
      "    status = run_func(*args)\n",
      "  File \"C:\\Users\\Work\\anaconda3\\lib\\site-packages\\pip\\_internal\\cli\\req_command.py\", line 248, in wrapper\n",
      "    return func(self, options, args)\n",
      "  File \"C:\\Users\\Work\\anaconda3\\lib\\site-packages\\pip\\_internal\\commands\\install.py\", line 449, in run\n",
      "    installed = install_given_reqs(\n",
      "  File \"C:\\Users\\Work\\anaconda3\\lib\\site-packages\\pip\\_internal\\req\\__init__.py\", line 67, in install_given_reqs\n",
      "    uninstalled_pathset = requirement.uninstall(auto_confirm=True)\n",
      "  File \"C:\\Users\\Work\\anaconda3\\lib\\site-packages\\pip\\_internal\\req\\req_install.py\", line 680, in uninstall\n",
      "    uninstalled_pathset.remove(auto_confirm, verbose)\n",
      "  File \"C:\\Users\\Work\\anaconda3\\lib\\site-packages\\pip\\_internal\\req\\req_uninstall.py\", line 372, in remove\n",
      "    logger.info(\"Uninstalling %s:\", dist_name_version)\n",
      "  File \"C:\\Users\\Work\\anaconda3\\lib\\logging\\__init__.py\", line 1446, in info\n",
      "    self._log(INFO, msg, args, **kwargs)\n",
      "  File \"C:\\Users\\Work\\anaconda3\\lib\\logging\\__init__.py\", line 1589, in _log\n",
      "    self.handle(record)\n",
      "  File \"C:\\Users\\Work\\anaconda3\\lib\\logging\\__init__.py\", line 1599, in handle\n",
      "    self.callHandlers(record)\n",
      "  File \"C:\\Users\\Work\\anaconda3\\lib\\logging\\__init__.py\", line 1661, in callHandlers\n",
      "    hdlr.handle(record)\n",
      "  File \"C:\\Users\\Work\\anaconda3\\lib\\logging\\__init__.py\", line 952, in handle\n",
      "    self.emit(record)\n",
      "  File \"C:\\Users\\Work\\anaconda3\\lib\\site-packages\\pip\\_internal\\utils\\logging.py\", line 179, in emit\n",
      "    self.handleError(record)\n",
      "Message: 'Uninstalling %s:'\n",
      "Arguments: ('Password-package-1.0.0',)\n",
      "--- Logging error ---\n",
      "Traceback (most recent call last):\n",
      "  File \"C:\\Users\\Work\\anaconda3\\lib\\site-packages\\pip\\_internal\\utils\\logging.py\", line 177, in emit\n",
      "    self.console.print(renderable, overflow=\"ignore\", crop=False, style=style)\n",
      "  File \"C:\\Users\\Work\\anaconda3\\lib\\site-packages\\pip\\_vendor\\rich\\console.py\", line 1719, in print\n",
      "    self._buffer.extend(new_segments)\n",
      "  File \"C:\\Users\\Work\\anaconda3\\lib\\site-packages\\pip\\_vendor\\rich\\console.py\", line 864, in __exit__\n",
      "    self._exit_buffer()\n",
      "  File \"C:\\Users\\Work\\anaconda3\\lib\\site-packages\\pip\\_vendor\\rich\\console.py\", line 822, in _exit_buffer\n",
      "    self._check_buffer()\n",
      "  File \"C:\\Users\\Work\\anaconda3\\lib\\site-packages\\pip\\_vendor\\rich\\console.py\", line 2027, in _check_buffer\n",
      "    legacy_windows_render(buffer, LegacyWindowsTerm(self.file))\n",
      "  File \"C:\\Users\\Work\\anaconda3\\lib\\site-packages\\pip\\_vendor\\rich\\_windows_renderer.py\", line 19, in legacy_windows_render\n",
      "    term.write_text(text)\n",
      "  File \"C:\\Users\\Work\\anaconda3\\lib\\site-packages\\pip\\_vendor\\rich\\_win32_console.py\", line 403, in write_text\n",
      "    self.write(text)\n",
      "  File \"C:\\Users\\Work\\anaconda3\\lib\\encodings\\cp1251.py\", line 19, in encode\n",
      "    return codecs.charmap_encode(input,self.errors,encoding_table)[0]\n",
      "UnicodeEncodeError: 'charmap' codec can't encode character '\\xf6' in position 77: character maps to <undefined>\n",
      "Call stack:\n",
      "  File \"C:\\Users\\Work\\anaconda3\\lib\\runpy.py\", line 197, in _run_module_as_main\n",
      "    return _run_code(code, main_globals, None,\n",
      "  File \"C:\\Users\\Work\\anaconda3\\lib\\runpy.py\", line 87, in _run_code\n",
      "    exec(code, run_globals)\n",
      "  File \"C:\\Users\\Work\\anaconda3\\Scripts\\pip.exe\\__main__.py\", line 7, in <module>\n",
      "    sys.exit(main())\n",
      "  File \"C:\\Users\\Work\\anaconda3\\lib\\site-packages\\pip\\_internal\\cli\\main.py\", line 79, in main\n",
      "    return command.main(cmd_args)\n",
      "  File \"C:\\Users\\Work\\anaconda3\\lib\\site-packages\\pip\\_internal\\cli\\base_command.py\", line 101, in main\n",
      "    return self._main(args)\n",
      "  File \"C:\\Users\\Work\\anaconda3\\lib\\site-packages\\pip\\_internal\\cli\\base_command.py\", line 223, in _main\n",
      "    return run(options, args)\n",
      "  File \"C:\\Users\\Work\\anaconda3\\lib\\site-packages\\pip\\_internal\\cli\\base_command.py\", line 169, in exc_logging_wrapper\n",
      "    status = run_func(*args)\n",
      "  File \"C:\\Users\\Work\\anaconda3\\lib\\site-packages\\pip\\_internal\\cli\\req_command.py\", line 248, in wrapper\n",
      "    return func(self, options, args)\n",
      "  File \"C:\\Users\\Work\\anaconda3\\lib\\site-packages\\pip\\_internal\\commands\\install.py\", line 449, in run\n",
      "    installed = install_given_reqs(\n",
      "  File \"C:\\Users\\Work\\anaconda3\\lib\\site-packages\\pip\\_internal\\req\\__init__.py\", line 67, in install_given_reqs\n",
      "    uninstalled_pathset = requirement.uninstall(auto_confirm=True)\n",
      "  File \"C:\\Users\\Work\\anaconda3\\lib\\site-packages\\pip\\_internal\\req\\req_install.py\", line 680, in uninstall\n",
      "    uninstalled_pathset.remove(auto_confirm, verbose)\n",
      "  File \"C:\\Users\\Work\\anaconda3\\lib\\site-packages\\pip\\_internal\\req\\req_uninstall.py\", line 387, in remove\n",
      "    logger.info(\"Successfully uninstalled %s\", dist_name_version)\n",
      "  File \"C:\\Users\\Work\\anaconda3\\lib\\logging\\__init__.py\", line 1446, in info\n",
      "    self._log(INFO, msg, args, **kwargs)\n",
      "  File \"C:\\Users\\Work\\anaconda3\\lib\\logging\\__init__.py\", line 1589, in _log\n",
      "    self.handle(record)\n",
      "  File \"C:\\Users\\Work\\anaconda3\\lib\\logging\\__init__.py\", line 1599, in handle\n",
      "    self.callHandlers(record)\n",
      "  File \"C:\\Users\\Work\\anaconda3\\lib\\logging\\__init__.py\", line 1661, in callHandlers\n",
      "    hdlr.handle(record)\n",
      "  File \"C:\\Users\\Work\\anaconda3\\lib\\logging\\__init__.py\", line 952, in handle\n",
      "    self.emit(record)\n",
      "  File \"C:\\Users\\Work\\anaconda3\\lib\\site-packages\\pip\\_internal\\utils\\logging.py\", line 179, in emit\n",
      "    self.handleError(record)\n",
      "Message: 'Successfully uninstalled %s'\n",
      "Arguments: ('Password-package-1.0.0',)\n",
      "--- Logging error ---\n",
      "Traceback (most recent call last):\n",
      "  File \"C:\\Users\\Work\\anaconda3\\lib\\site-packages\\pip\\_internal\\utils\\logging.py\", line 177, in emit\n",
      "    self.console.print(renderable, overflow=\"ignore\", crop=False, style=style)\n",
      "  File \"C:\\Users\\Work\\anaconda3\\lib\\site-packages\\pip\\_vendor\\rich\\console.py\", line 1719, in print\n",
      "    self._buffer.extend(new_segments)\n",
      "  File \"C:\\Users\\Work\\anaconda3\\lib\\site-packages\\pip\\_vendor\\rich\\console.py\", line 864, in __exit__\n",
      "    self._exit_buffer()\n",
      "  File \"C:\\Users\\Work\\anaconda3\\lib\\site-packages\\pip\\_vendor\\rich\\console.py\", line 822, in _exit_buffer\n",
      "    self._check_buffer()\n",
      "  File \"C:\\Users\\Work\\anaconda3\\lib\\site-packages\\pip\\_vendor\\rich\\console.py\", line 2027, in _check_buffer\n",
      "    legacy_windows_render(buffer, LegacyWindowsTerm(self.file))\n",
      "  File \"C:\\Users\\Work\\anaconda3\\lib\\site-packages\\pip\\_vendor\\rich\\_windows_renderer.py\", line 19, in legacy_windows_render\n",
      "    term.write_text(text)\n",
      "  File \"C:\\Users\\Work\\anaconda3\\lib\\site-packages\\pip\\_vendor\\rich\\_win32_console.py\", line 403, in write_text\n",
      "    self.write(text)\n",
      "  File \"C:\\Users\\Work\\anaconda3\\lib\\encodings\\cp1251.py\", line 19, in encode\n",
      "    return codecs.charmap_encode(input,self.errors,encoding_table)[0]\n",
      "UnicodeEncodeError: 'charmap' codec can't encode character '\\xf6' in position 77: character maps to <undefined>\n",
      "Call stack:\n",
      "  File \"C:\\Users\\Work\\anaconda3\\lib\\runpy.py\", line 197, in _run_module_as_main\n",
      "    return _run_code(code, main_globals, None,\n",
      "  File \"C:\\Users\\Work\\anaconda3\\lib\\runpy.py\", line 87, in _run_code\n",
      "    exec(code, run_globals)\n",
      "  File \"C:\\Users\\Work\\anaconda3\\Scripts\\pip.exe\\__main__.py\", line 7, in <module>\n",
      "    sys.exit(main())\n",
      "  File \"C:\\Users\\Work\\anaconda3\\lib\\site-packages\\pip\\_internal\\cli\\main.py\", line 79, in main\n",
      "    return command.main(cmd_args)\n",
      "  File \"C:\\Users\\Work\\anaconda3\\lib\\site-packages\\pip\\_internal\\cli\\base_command.py\", line 101, in main\n",
      "    return self._main(args)\n",
      "  File \"C:\\Users\\Work\\anaconda3\\lib\\site-packages\\pip\\_internal\\cli\\base_command.py\", line 223, in _main\n",
      "    return run(options, args)\n",
      "  File \"C:\\Users\\Work\\anaconda3\\lib\\site-packages\\pip\\_internal\\cli\\base_command.py\", line 169, in exc_logging_wrapper\n",
      "    status = run_func(*args)\n",
      "  File \"C:\\Users\\Work\\anaconda3\\lib\\site-packages\\pip\\_internal\\cli\\req_command.py\", line 248, in wrapper\n",
      "    return func(self, options, args)\n",
      "  File \"C:\\Users\\Work\\anaconda3\\lib\\site-packages\\pip\\_internal\\commands\\install.py\", line 489, in run\n",
      "    write_output(\n",
      "  File \"C:\\Users\\Work\\anaconda3\\lib\\site-packages\\pip\\_internal\\utils\\misc.py\", line 338, in write_output\n",
      "    logger.info(msg, *args)\n",
      "  File \"C:\\Users\\Work\\anaconda3\\lib\\logging\\__init__.py\", line 1446, in info\n",
      "    self._log(INFO, msg, args, **kwargs)\n",
      "  File \"C:\\Users\\Work\\anaconda3\\lib\\logging\\__init__.py\", line 1589, in _log\n",
      "    self.handle(record)\n",
      "  File \"C:\\Users\\Work\\anaconda3\\lib\\logging\\__init__.py\", line 1599, in handle\n",
      "    self.callHandlers(record)\n",
      "  File \"C:\\Users\\Work\\anaconda3\\lib\\logging\\__init__.py\", line 1661, in callHandlers\n",
      "    hdlr.handle(record)\n",
      "  File \"C:\\Users\\Work\\anaconda3\\lib\\logging\\__init__.py\", line 952, in handle\n",
      "    self.emit(record)\n",
      "  File \"C:\\Users\\Work\\anaconda3\\lib\\site-packages\\pip\\_internal\\utils\\logging.py\", line 179, in emit\n",
      "    self.handleError(record)\n",
      "Message: 'Successfully installed %s'\n",
      "Arguments: ('Password-package-1.0.0',)\n"
     ]
    }
   ],
   "source": [
    "import sys\n",
    "sys.stdout.encoding = 'utf-8'\n",
    "\n",
    "!pip install ."
   ]
  },
  {
   "cell_type": "code",
   "execution_count": 7,
   "id": "302368fc",
   "metadata": {},
   "outputs": [
    {
     "ename": "AttributeError",
     "evalue": "module 'sys' has no attribute 'setdefaultencoding'",
     "output_type": "error",
     "traceback": [
      "\u001b[1;31m---------------------------------------------------------------------------\u001b[0m",
      "\u001b[1;31mAttributeError\u001b[0m                            Traceback (most recent call last)",
      "\u001b[1;32m~\\AppData\\Local\\Temp\\ipykernel_120\\767772611.py\u001b[0m in \u001b[0;36m<module>\u001b[1;34m\u001b[0m\n\u001b[0;32m      3\u001b[0m \u001b[1;33m\u001b[0m\u001b[0m\n\u001b[0;32m      4\u001b[0m \u001b[0mimportlib\u001b[0m\u001b[1;33m.\u001b[0m\u001b[0mreload\u001b[0m\u001b[1;33m(\u001b[0m\u001b[0msys\u001b[0m\u001b[1;33m)\u001b[0m\u001b[1;33m\u001b[0m\u001b[1;33m\u001b[0m\u001b[0m\n\u001b[1;32m----> 5\u001b[1;33m \u001b[0msys\u001b[0m\u001b[1;33m.\u001b[0m\u001b[0msetdefaultencoding\u001b[0m\u001b[1;33m(\u001b[0m\u001b[1;34m'utf-8'\u001b[0m\u001b[1;33m)\u001b[0m\u001b[1;33m\u001b[0m\u001b[1;33m\u001b[0m\u001b[0m\n\u001b[0m",
      "\u001b[1;31mAttributeError\u001b[0m: module 'sys' has no attribute 'setdefaultencoding'"
     ]
    }
   ],
   "source": [
    "import importlib\n",
    "import sys\n",
    "\n",
    "importlib.reload(sys)\n",
    "sys.setdefaultencoding('utf-8')"
   ]
  },
  {
   "cell_type": "code",
   "execution_count": null,
   "id": "d39e6360",
   "metadata": {},
   "outputs": [],
   "source": []
  }
 ],
 "metadata": {
  "kernelspec": {
   "display_name": "Python 3 (ipykernel)",
   "language": "python",
   "name": "python3"
  },
  "language_info": {
   "codemirror_mode": {
    "name": "ipython",
    "version": 3
   },
   "file_extension": ".py",
   "mimetype": "text/x-python",
   "name": "python",
   "nbconvert_exporter": "python",
   "pygments_lexer": "ipython3",
   "version": "3.9.13"
  }
 },
 "nbformat": 4,
 "nbformat_minor": 5
}
